<?xml version="1.0" encoding="utf-8"?>
<!-- This URDF was automatically created by SolidWorks to URDF Exporter! Originally created by Stephen Brawner (brawner@gmail.com) 
     Commit Version: 1.6.0-1-g15f4949  Build Version: 1.6.7594.29634
     For more information, please see http://wiki.ros.org/sw_urdf_exporter -->
<robot
  name="k100">
  <link name="world"/>
  <joint name="world_to_base" type="fixed">
    <parent link="world"/>
    <child link="base_link"/>
    <origin xyz="0 0 0" rpy="0 0 0"/>
  </joint>
  <link
    name="base_link">
    <inertial>
      <origin
        xyz="-0.24697 -0.003266 0.43754"
        rpy="0 0 0" />
      <mass
        value="10.058" />
      <inertia
        ixx="0.11397"
        ixy="0.001501"
        ixz="0.0065128"
        iyy="0.11493"
        iyz="-2.0398E-05"
        izz="0.13655" />
    </inertial>
    <visual>
      <origin
        xyz="0 0 0"
        rpy="0 0 0" />
      <geometry>
        <mesh
          filename="package://k100_description/meshes/k100/base_link.STL" />
      </geometry>
      <material
        name="">
        <color
          rgba="1 1 1 1" />
      </material>
    </visual>
    <collision>
      <origin
        xyz="0 0 0"
        rpy="0 0 0" />
      <geometry>
        <mesh
          filename="package://k100_description/meshes/k100/base_link.STL" />
      </geometry>
    </collision>
  </link>
  <link
    name="head_yaw_link">
    <inertial>
      <origin
        xyz="0.0093095 -2.7111E-06 0.019585"
        rpy="0 0 0" />
      <mass
        value="0.033177" />
      <inertia
        ixx="1.0238E-05"
        ixy="2.0171E-07"
        ixz="2.8308E-06"
        iyy="3.6739E-05"
        iyz="-1.7681E-09"
        izz="3.7525E-05" />
    </inertial>
    <visual>
      <origin
        xyz="0 0 0"
        rpy="0 0 0" />
      <geometry>
        <mesh
          filename="package://k100_description/meshes/k100/head_yaw_link.STL" />
      </geometry>
      <material
        name="">
        <color
          rgba="1 1 1 1" />
      </material>
    </visual>
    <collision>
      <origin
        xyz="0 0 0"
        rpy="0 0 0" />
      <geometry>
        <mesh
          filename="package://k100_description/meshes/k100/head_yaw_link.STL" />
      </geometry>
    </collision>
  </link>
  <joint name="head_yaw_joint" type="revolute">
    <origin
      xyz="-0.2915 0 1.3065"
      rpy="0 0 0" />
    <parent
      link="base_link" />
    <child
      link="head_yaw_link" />
    <axis
      xyz="0 0 1" />
    <limit
      lower="-1"
      upper="1"
      effort="0"
      velocity="0" />
  </joint>
  <link
    name="head_pitch_link">
    <inertial>
      <origin
        xyz="-0.010336 0.043982 0.046524"
        rpy="0 0 0" />
      <mass
        value="0.34565" />
      <inertia
        ixx="0.0012251"
        ixy="1.6043E-06"
        ixz="0.00020762"
        iyy="0.0013023"
        iyz="-3.6288E-07"
        izz="0.0012224" />
    </inertial>
    <visual>
      <origin
        xyz="0 0 0"
        rpy="0 0 0" />
      <geometry>
        <mesh
          filename="package://k100_description/meshes/k100/head_pitch_link.STL" />
      </geometry>
      <material
        name="">
        <color
          rgba="1 1 1 1" />
      </material>
    </visual>
    <collision>
      <origin
        xyz="0 0 0"
        rpy="0 0 0" />
      <geometry>
        <mesh
          filename="package://k100_description/meshes/k100/head_pitch_link.STL" />
      </geometry>
    </collision>
  </link>
  <joint
    name="head_pitch_joint"
    type="revolute">
    <origin
      xyz="0.034003 -0.044 0.05251"
      rpy="0 0 0" />
    <parent
      link="head_yaw_link" />
    <child
      link="head_pitch_link" />
    <axis
      xyz="0 -1 0" />
    <limit
      lower="-1"
      upper="1"
      effort="0"
      velocity="0" />
  </joint>
  <link
    name="left_shoulder_pitch_link">
    <inertial>
      <origin
        xyz="-4.5858E-06 0.00022929 0.037911"
        rpy="0 0 0" />
      <mass
        value="0.032279" />
      <inertia
        ixx="3.4609E-05"
        ixy="2.6745E-08"
        ixz="-6.4702E-09"
        iyy="4.7862E-05"
        iyz="-3.7781E-07"
        izz="2.2147E-05" />
    </inertial>
    <visual>
      <origin
        xyz="0 0 0"
        rpy="0 0 0" />
      <geometry>
        <mesh
          filename="package://k100_description/meshes/k100/left_shoulder_pitch_link.STL" />
      </geometry>
      <material
        name="">
        <color
          rgba="1 1 1 1" />
      </material>
    </visual>
    <collision>
      <origin
        xyz="0 0 0"
        rpy="0 0 0" />
      <geometry>
        <mesh
          filename="package://k100_description/meshes/k100/left_shoulder_pitch_link.STL" />
      </geometry>
    </collision>
  </link>
  <joint
    name="left_shoulder_pitch_joint"
    type="revolute">
    <origin
      xyz="-0.29331 0.15637 1.1789"
      rpy="-1.5708 0 0" />
    <parent
      link="base_link" />
    <child
      link="left_shoulder_pitch_link" />
    <axis
      xyz="0 0 1" />
    <limit
      lower="-3.0229102644541785"
      upper="3.005456971934235"
      effort="10"
      velocity="100" />
  </joint>
  <link
    name="left_shoulder_roll_link">
    <inertial>
      <origin
        xyz="0.0529817223822346 0.000381292922410348 -0.0482468772809825"
        rpy="0 0 0" />
      <mass
        value="0.168282055709579" />
      <inertia
        ixx="0.000490405565826638"
        ixy="1.69743273244684E-07"
        ixz="-1.64076112806147E-06"
        iyy="0.000378920723871357"
        iyz="-8.62858713273323E-06"
        izz="0.000220523090720176" />
    </inertial>
    <visual>
      <origin
        xyz="0 0 0"
        rpy="0 0 0" />
      <geometry>
        <mesh
          filename="package://k100_description/meshes/k100/left_shoulder_roll_link.STL" />
      </geometry>
      <material
        name="">
        <color
          rgba="1 1 1 1" />
      </material>
    </visual>
    <collision>
      <origin
        xyz="0 0 0"
        rpy="0 0 0" />
      <geometry>
        <mesh
          filename="package://k100_description/meshes/k100/left_shoulder_roll_link.STL" />
      </geometry>
    </collision>
  </link>
  <joint
    name="left_shoulder_roll_joint"
    type="revolute">
    <origin
      xyz="-0.052528 0 0.057497"
      rpy="1.5708 0 0" />
    <parent
      link="left_shoulder_pitch_link" />
    <child
      link="left_shoulder_roll_link" />
    <axis
      xyz="-1 0 0" />
    <limit
      lower="-3.4033920413889422"
      upper="0.3490658503988659"
      effort="10"
      velocity="100" />
  </joint>
  <link
    name="left_shoulder_yaw_link">
    <inertial>
      <origin
        xyz="0.047728 -0.21486 -0.58242"
        rpy="0 0 0" />
      <mass
        value="13.966" />
      <inertia
        ixx="2.7495"
        ixy="-0.00097403"
        ixz="0.10462"
        iyy="2.6756"
        iyz="0.040666"
        izz="0.52568" />
    </inertial>
    <visual>
      <origin
        xyz="0 0 0"
        rpy="0 0 0" />
      <geometry>
        <mesh
          filename="package://k100_description/meshes/k100/left_shoulder_yaw_link.STL" />
      </geometry>
      <material
        name="">
        <color
          rgba="1 1 1 1" />
      </material>
    </visual>
    <collision>
      <origin
        xyz="0 0 0"
        rpy="0 0 0" />
      <geometry>
        <mesh
          filename="package://k100_description/meshes/k100/left_shoulder_yaw_link.STL" />
      </geometry>
    </collision>
  </link>
  <joint
    name="left_shoulder_yaw_joint"
    type="revolute">
    <origin
      xyz="0.052528 0 -0.1236"
      rpy="0 0 0" />
    <parent
      link="left_shoulder_roll_link" />
    <child
      link="left_shoulder_yaw_link" />
    <axis
      xyz="0 0 -1" />
    <limit
      lower="-1.5707963267948966"
      upper="3.141592653589793"
      effort="10"
      velocity="100" />
  </joint>
  <link
    name="left_elbow_link">
    <inertial>
      <origin
        xyz="-0.012869743810657 0.000118692786157143 -0.02840138793709"
        rpy="0 0 0" />
      <mass
        value="0.165774576195281" />
      <inertia
        ixx="0.000284792774512073"
        ixy="-1.15754165048357E-06"
        ixz="-4.79563912327492E-05"
        iyy="0.000429664716893545"
        iyz="-1.77355295217618E-06"
        izz="0.000243113442796536" />
    </inertial>
    <visual>
      <origin
        xyz="0 0 0"
        rpy="0 0 0" />
      <geometry>
        <mesh
          filename="package://k100_description/meshes/k100/left_elbow_link.STL" />
      </geometry>
      <material
        name="">
        <color
          rgba="1 1 1 1" />
      </material>
    </visual>
    <collision>
      <origin
        xyz="0 0 0"
        rpy="0 0 0" />
      <geometry>
        <mesh
          filename="package://k100_description/meshes/k100/left_elbow_link.STL" />
      </geometry>
    </collision>
  </link>
  <joint
    name="left_elbow_joint"
    type="revolute">
    <origin
      xyz="0.024 0 -0.0964"
      rpy="0 0 0" />
    <parent
      link="left_shoulder_yaw_link" />
    <child
      link="left_elbow_link" />
    <axis
      xyz="0 -1 0" />
    <limit
      lower="-1.5707963267948966"
      upper="2.871066619530672"
      effort="10"
      velocity="100" />
  </joint>
  <link
    name="left_wrist_roll_link">
    <inertial>
      <origin
        xyz="0.0019178 0.00010108 -0.057332"
        rpy="0 0 0" />
      <mass
        value="0.11845" />
      <inertia
        ixx="0.00025823"
        ixy="-2.2846E-08"
        ixz="-1.1422E-08"
        iyy="0.00016834"
        iyz="5.6665E-07"
        izz="0.00012666" />
    </inertial>
    <visual>
      <origin
        xyz="0 0 0"
        rpy="0 0 0" />
      <geometry>
        <mesh
          filename="package://k100_description/meshes/k100/left_wrist_roll_link.STL" />
      </geometry>
      <material
        name="">
        <color
          rgba="1 1 1 1" />
      </material>
    </visual>
    <collision>
      <origin
        xyz="0 0 0"
        rpy="0 0 0" />
      <geometry>
        <mesh
          filename="package://k100_description/meshes/k100/left_wrist_roll_link.STL" />
      </geometry>
    </collision>
  </link>
  <joint
    name="left_wrist_roll_joint"
    type="revolute">
    <origin
      xyz="-0.02574 0 -0.094"
      rpy="0 0 0" />
    <parent
      link="left_elbow_link" />
    <child
      link="left_wrist_roll_link" />
    <axis
      xyz="0 0 -1" />
    <limit
      lower="-2.9670597283903604"
      upper="3.01941960595019"
      effort="10"
      velocity="100" />
  </joint>
  <link
    name="left_wrist_pitch_link">
    <inertial>
      <origin
        xyz="-0.000376443250173261 0.0385887267181524 -0.0284852092797504"
        rpy="0 0 0" />
      <mass
        value="0.0508307380202339" />
      <inertia
        ixx="6.07885115247108E-05"
        ixy="-6.74245978776449E-09"
        ixz="-5.22922284897702E-07"
        iyy="6.71946692283685E-05"
        iyz="-4.67909273179692E-07"
        izz="1.93580958562299E-05" />
    </inertial>
    <visual>
      <origin
        xyz="0 0 0"
        rpy="0 0 0" />
      <geometry>
        <mesh
          filename="package://k100_description/meshes/k100/left_wrist_pitch_link.STL" />
      </geometry>
      <material
        name="">
        <color
          rgba="1 1 1 1" />
      </material>
    </visual>
    <collision>
      <origin
        xyz="0 0 0"
        rpy="0 0 0" />
      <geometry>
        <mesh
          filename="package://k100_description/meshes/k100/left_wrist_pitch_link.STL" />
      </geometry>
    </collision>
  </link>
  <joint
    name="left_wrist_pitch_joint"
    type="revolute">
    <origin
      xyz="0.0017429 -0.03829 -0.152"
      rpy="0 0 0" />
    <parent
      link="left_wrist_roll_link" />
    <child
      link="left_wrist_pitch_link" />
    <axis
      xyz="0 -1 0" />
    <limit
      lower="-1.8151424220741028"
      upper="1.8849555921538759"
      effort="10"
      velocity="100" />
  </joint>
  <link
    name="left_wrist_yaw_link">
    <inertial>
      <origin
        xyz="-0.026886 0.02123 -0.053746"
        rpy="0 0 0" />
      <mass
        value="0.15595" />
      <inertia
        ixx="6.5671E-05"
        ixy="-4.9995E-08"
        ixz="9.659E-09"
        iyy="5.3338E-05"
        iyz="5.4196E-06"
        izz="6.5262E-05" />
    </inertial>
    <visual>
      <origin
        xyz="0 0 0"
        rpy="0 0 0" />
      <geometry>
        <mesh
          filename="package://k100_description/meshes/k100/left_wrist_yaw_link.STL" />
      </geometry>
      <material
        name="">
        <color
          rgba="1 1 1 1" />
      </material>
    </visual>
    <collision>
      <origin
        xyz="0 0 0"
        rpy="0 0 0" />
      <geometry>
        <mesh
          filename="package://k100_description/meshes/k100/left_wrist_yaw_link.STL" />
      </geometry>
    </collision>
  </link>
  <joint
    name="left_wrist_yaw_joint"
    type="revolute">
    <origin
      xyz="0.026797 0.0383 -0.053999"
      rpy="0 0 0" />
    <parent
      link="left_wrist_pitch_link" />
    <child
      link="left_wrist_yaw_link" />
    <axis
      xyz="1 0 0" />
    <limit
      lower="-1.5707963267948966"
      upper="1.605702911834783"
      effort="10"
      velocity="100" />
  </joint>
  <link
    name="right_shoulder_pitch_link">
    <inertial>
      <origin
        xyz="4.3409E-06 -0.00022905 0.043911"
        rpy="0 0 0" />
      <mass
        value="0.032279" />
      <inertia
        ixx="3.4609E-05"
        ixy="2.6745E-08"
        ixz="6.4702E-09"
        iyy="4.7862E-05"
        iyz="3.7781E-07"
        izz="2.2147E-05" />
    </inertial>
    <visual>
      <origin
        xyz="0 0 0"
        rpy="0 0 0" />
      <geometry>
        <mesh
          filename="package://k100_description/meshes/k100/right_shoulder_pitch_link.STL" />
      </geometry>
      <material
        name="">
        <color
          rgba="1 1 1 1" />
      </material>
    </visual>
    <collision>
      <origin
        xyz="0 0 0"
        rpy="0 0 0" />
      <geometry>
        <mesh
          filename="package://k100_description/meshes/k100/right_shoulder_pitch_link.STL" />
      </geometry>
    </collision>
  </link>
  <joint
    name="right_shoulder_pitch_joint"
    type="revolute">
    <origin
      xyz="-0.29331 -0.15184 1.1789"
      rpy="1.5708 0 0" />
    <parent
      link="base_link" />
    <child
      link="right_shoulder_pitch_link" />
    <axis
      xyz="0 0 -1" />
    <limit
      lower="-3.0229102644541785"
      upper="3.005456971934235"
      effort="10"
      velocity="100" />
  </joint>
  <link
    name="right_shoulder_roll_link">
    <inertial>
      <origin
        xyz="0.00039109 -0.0003817 -0.048245"
        rpy="0 0 0" />
      <mass
        value="0.16826" />
      <inertia
        ixx="0.00049035"
        ixy="2.6217E-07"
        ixz="2.8524E-07"
        iyy="0.00037893"
        iyz="8.6202E-06"
        izz="0.0002205" />
    </inertial>
    <visual>
      <origin
        xyz="0 0 0"
        rpy="0 0 0" />
      <geometry>
        <mesh
          filename="package://k100_description/meshes/k100/right_shoulder_roll_link.STL" />
      </geometry>
      <material
        name="">
        <color
          rgba="1 1 1 1" />
      </material>
    </visual>
    <collision>
      <origin
        xyz="0 0 0"
        rpy="0 0 0" />
      <geometry>
        <mesh
          filename="package://k100_description/meshes/k100/right_shoulder_roll_link.STL" />
      </geometry>
    </collision>
  </link>
  <joint
    name="right_shoulder_roll_joint"
    type="revolute">
    <origin
      xyz="0 0 0.063497"
      rpy="-1.5708 0 0" />
    <parent
      link="right_shoulder_pitch_link" />
    <child
      link="right_shoulder_roll_link" />
    <axis
      xyz="1 0 0" />
    <limit
      lower="-3.4033920413889422"
      upper="0.29670597283903605"
      effort="10"
      velocity="100" />
  </joint>

  <link
    name="right_shoulder_yaw_link">
    <inertial>
      <origin
        xyz="0.047728 0.21434 -0.58242"
        rpy="0 0 0" />
      <mass
        value="13.966" />
      <inertia
        ixx="2.7495"
        ixy="-0.00097403"
        ixz="0.10462"
        iyy="2.6756"
        iyz="0.040666"
        izz="0.52568" />
    </inertial>
    <visual>
      <origin
        xyz="0 0 0"
        rpy="0 0 0" />
      <geometry>
        <mesh
          filename="package://k100_description/meshes/k100/right_shoulder_yaw_link.STL" />
      </geometry>
      <material
        name="">
        <color
          rgba="1 1 1 1" />
      </material>
    </visual>
    <collision>
      <origin
        xyz="0 0 0"
        rpy="0 0 0" />
      <geometry>
        <mesh
          filename="package://k100_description/meshes/k100/right_shoulder_yaw_link.STL" />
      </geometry>
    </collision>
  </link>
  <joint
    name="right_shoulder_yaw_joint"
    type="revolute">
    <origin
      xyz="0 0 -0.1236"
      rpy="0 0 0" />
    <parent
      link="right_shoulder_roll_link" />
    <child
      link="right_shoulder_yaw_link" />
    <axis
      xyz="0 0 1" />
    <limit
      lower="-1.5707963267948966"
      upper="3.141592653589793"
      effort="10"
      velocity="100" />
  </joint>
  <link
    name="right_elbow_link">
    <inertial>
      <origin
        xyz="-0.012827 -0.0009453 -0.028372"
        rpy="0 0 0" />
      <mass
        value="0.16555" />
      <inertia
        ixx="0.00028451"
        ixy="6.8087E-07"
        ixz="-4.7913E-05"
        iyy="0.00042913"
        iyz="2.0386E-06"
        izz="0.00024258" />
    </inertial>
    <visual>
      <origin
        xyz="0 0 0"
        rpy="0 0 0" />
      <geometry>
        <mesh
          filename="package://k100_description/meshes/k100/right_elbow_link.STL" />
      </geometry>
      <material
        name="">
        <color
          rgba="1 1 1 1" />
      </material>
    </visual>
    <collision>
      <origin
        xyz="0 0 0"
        rpy="0 0 0" />
      <geometry>
        <mesh
          filename="package://k100_description/meshes/k100/right_elbow_link.STL" />
      </geometry>
    </collision>
  </link>
  <joint
    name="right_elbow_joint"
    type="revolute">
    <origin
      xyz="0.024 0.0003 -0.0964"
      rpy="0 0 0" />
    <parent
      link="right_shoulder_yaw_link" />
    <child
      link="right_elbow_link" />
    <axis
      xyz="0 -1 0" />
    <limit
      lower="-1.5533430342749535"
      upper="2.897246558310587"
      effort="10"
      velocity="100" />
  </joint>
  <link
    name="right_wrist_roll_link">
    <inertial>
      <origin
        xyz="0.0019175 0.0001012 -0.057332"
        rpy="0 0 0" />
      <mass
        value="0.11845" />
      <inertia
        ixx="0.00025823"
        ixy="-2.314E-08"
        ixz="-1.1321E-08"
        iyy="0.00016834"
        iyz="5.6668E-07"
        izz="0.00012666" />
    </inertial>
    <visual>
      <origin
        xyz="0 0 0"
        rpy="0 0 0" />
      <geometry>
        <mesh
          filename="package://k100_description/meshes/k100/right_wrist_roll_link.STL" />
      </geometry>
      <material
        name="">
        <color
          rgba="1 1 1 1" />
      </material>
    </visual>
    <collision>
      <origin
        xyz="0 0 0"
        rpy="0 0 0" />
      <geometry>
        <mesh
          filename="package://k100_description/meshes/k100/right_wrist_roll_link.STL" />
      </geometry>
    </collision>
  </link>
  <joint
    name="right_wrist_roll_joint"
    type="revolute">
    <origin
      xyz="-0.02574 -0.00030967 -0.094"
      rpy="0 0 0" />
      
    <parent
      link="right_elbow_link" />
    <child
      link="right_wrist_roll_link" />
   <axis
      xyz="0 0 1" />
    <limit
      lower="-1.8325957145940461"
      upper="1.8325957145940461"
      effort="10"
      velocity="100" />
  </joint>
  <link
    name="right_wrist_pitch_link">
    <inertial>
      <origin
        xyz="-0.00037598 0.037227 -0.028477"
        rpy="0 0 0" />
      <mass
        value="0.05082" />
      <inertia
        ixx="6.077E-05"
        ixy="1.5462E-09"
        ixz="-5.2222E-07"
        iyy="6.7177E-05"
        iyz="5.052E-07"
        izz="1.9356E-05" />
    </inertial>
    <visual>
      <origin
        xyz="0 0 0"
        rpy="0 0 0" />
      <geometry>
        <mesh
          filename="package://k100_description/meshes/k100/right_wrist_pitch_link.STL" />
      </geometry>
      <material
        name="">
        <color
          rgba="1 1 1 1" />
      </material>
    </visual>
    <collision>
      <origin
        xyz="0 0 0"
        rpy="0 0 0" />
      <geometry>
        <mesh
          filename="package://k100_description/meshes/k100/right_wrist_pitch_link.STL" />
      </geometry>
    </collision>
  </link>
    <joint
    name="right_wrist_pitch_joint"
    type="revolute">
    <origin
      xyz="0.0017429 -0.03829 -0.152"
      rpy="0 0 0" />
    <parent
      link="right_wrist_roll_link" />
    <child
      link="right_wrist_pitch_link" />
     <axis
      xyz="0 -1 0" />
    <limit
      lower="-1.8325957145940461"
      upper="1.8325957145940461"
      effort="10"
      velocity="100" />
  </joint>
  <link
    name="right_wrist_yaw_link">
    <inertial>
      <origin
        xyz="-0.026833 -0.021351 -0.053746"
        rpy="0 0 0" />
      <mass
        value="0.15595" />
      <inertia
        ixx="6.5671E-05"
        ixy="-4.9993E-08"
        ixz="1.9957E-08"
        iyy="5.3338E-05"
        iyz="-5.9111E-06"
        izz="6.5262E-05" />
    </inertial>
    <visual>
      <origin
        xyz="0 0 0"
        rpy="0 0 0" />
      <geometry>
        <mesh
          filename="package://k100_description/meshes/k100/right_wrist_yaw_link.STL" />
      </geometry>
      <material
        name="">
        <color
          rgba="1 1 1 1" />
      </material>
    </visual>
    <collision>
      <origin
        xyz="0 0 0"
        rpy="0 0 0" />
      <geometry>
        <mesh
          filename="package://k100_description/meshes/k100/right_wrist_yaw_link.STL" />
      </geometry>
    </collision>
  </link>
  <joint
    name="right_wrist_yaw_joint"
    type="revolute">
    <origin
      xyz="0.026797 0.0383 -0.053999"
      rpy="0 0 0" />
    <parent
      link="right_wrist_pitch_link" />
    <child
      link="right_wrist_yaw_link" />
    <axis
      xyz="-1 0 0" />
    <limit
      lower="-1.5882496193148399"
      upper="1.5882496193148399"
      effort="10"
      velocity="100" />
  </joint>
  <link
    name="o_wheel1_Link">
    <inertial>
      <origin
        xyz="-6.8663E-06 -0.033131 5.3329E-06"
        rpy="0 0 0" />
      <mass
        value="0.49216" />
      <inertia
        ixx="0.0011111"
        ixy="-3.5628E-08"
        ixz="-5.8814E-09"
        iyy="0.0021452"
        iyz="1.3891E-08"
        izz="0.0011111" />
    </inertial>
    <visual>
      <origin
        xyz="0 0 0"
        rpy="0 0 0" />
      <geometry>
        <mesh
          filename="package://k100_description/meshes/k100/o_wheel1_Link.STL" />
      </geometry>
      <material
        name="">
        <color
          rgba="1 1 1 1" />
      </material>
    </visual>
    <collision>
      <origin
        xyz="0 0 0"
        rpy="0 0 0" />
      <geometry>
        <mesh
          filename="package://k100_description/meshes/k100/o_wheel1_Link.STL" />
      </geometry>
    </collision>
  </link>
  <joint
    name="w_body_wheel1_joint"
    type="fixed">
    <origin
      xyz="-0.2245 -0.1858 0.085"
      rpy="0 0 0" />
    <parent
      link="base_link" />
    <child
      link="o_wheel1_Link" />
    <axis
      xyz="0 -1 0" />
  </joint>
  <link
    name="o_wheel2_Link">
    <inertial>
      <origin
        xyz="-7.0583E-06 0.033132 5.0699E-06"
        rpy="0 0 0" />
      <mass
        value="0.49215" />
      <inertia
        ixx="0.0011111"
        ixy="3.4274E-08"
        ixz="-5.7353E-09"
        iyy="0.0021452"
        iyz="-1.5505E-08"
        izz="0.001111" />
    </inertial>
    <visual>
      <origin
        xyz="0 0 0"
        rpy="0 0 0" />
      <geometry>
        <mesh
          filename="package://k100_description/meshes/k100/o_wheel2_Link.STL" />
      </geometry>
      <material
        name="">
        <color
          rgba="1 1 1 1" />
      </material>
    </visual>
    <collision>
      <origin
        xyz="0 0 0"
        rpy="0 0 0" />
      <geometry>
        <mesh
          filename="package://k100_description/meshes/k100/o_wheel2_Link.STL" />
      </geometry>
    </collision>
  </link>
  <joint
    name="w_body_wheel2_joint"
    type="fixed">
    <origin
      xyz="-0.2245 0.1858 0.085"
      rpy="0 0 0" />
    <parent
      link="base_link" />
    <child
      link="o_wheel2_Link" />
    <axis
      xyz="0 1 0" />
  </joint>
  <link
    name="o_wheel3_Link">
    <inertial>
      <origin
        xyz="-0.0199999967173905 -1.09082498357946E-10 -0.0759999999999938"
        rpy="0 0 0" />
      <mass
        value="0.0865252381159967" />
      <inertia
        ixx="9.47065367250295E-05"
        ixy="3.97322843103075E-19"
        ixz="-3.9510490256026E-12"
        iyy="0.000182809576289922"
        iyz="-1.20119572882808E-19"
        izz="9.4688065891407E-05" />
    </inertial>
    <visual>
      <origin
        xyz="0 0 0"
        rpy="0 0 0" />
      <geometry>
        <mesh
          filename="package://k100_description/meshes/k100/o_wheel3_Link.STL" />
      </geometry>
      <material
        name="">
        <color
          rgba="1 1 1 1" />
      </material>
    </visual>
    <collision>
      <origin
        xyz="0 0 0"
        rpy="0 0 0" />
      <geometry>
        <mesh
          filename="package://k100_description/meshes/k100/o_wheel3_Link.STL" />
      </geometry>
    </collision>
  </link>
  <joint
    name="w_body_wheel3_joint"
    type="fixed">
    <origin
      xyz="-0.4445 0 0.126"
      rpy="0 0 0" />
    <parent
      link="base_link" />
    <child
      link="o_wheel3_Link" />
    <axis
      xyz="0 0 -1" />
  </joint>
  <link
    name="o_wheel3_1_Link">
    <inertial>
      <origin
        xyz="3.2825E-09 0.018 2.6532E-13"
        rpy="0 0 0" />
      <mass
        value="0.086525" />
      <inertia
        ixx="9.4707E-05"
        ixy="3.9732E-19"
        ixz="-3.951E-12"
        iyy="0.00018281"
        iyz="-1.2012E-19"
        izz="9.4688E-05" />
    </inertial>
    <visual>
      <origin
        xyz="0 0 0"
        rpy="0 0 0" />
      <geometry>
        <mesh
          filename="package://k100_description/meshes/k100/o_wheel3_1_Link.STL" />
      </geometry>
      <material
        name="">
        <color
          rgba="1 1 1 1" />
      </material>
    </visual>
    <collision>
      <origin
        xyz="0 0 0"
        rpy="0 0 0" />
      <geometry>
        <mesh
          filename="package://k100_description/meshes/k100/o_wheel3_1_Link.STL" />
      </geometry>
    </collision>
  </link>
  <joint
    name="w_body_wheel3_1_joint"
    type="fixed">
    <origin
      xyz="-0.02 -0.018 -0.076"
      rpy="0 0 0" />
    <parent
      link="o_wheel3_Link" />
    <child
      link="o_wheel3_1_Link" />
    <axis
      xyz="0 -1 0" />
  </joint>
  <link
    name="o_wheel4_Link">
    <inertial>
      <origin
        xyz="-0.00028246 0.019998 -0.076"
        rpy="0 0 0" />
      <mass
        value="0.086776" />
      <inertia
        ixx="0.0001828"
        ixy="1.2442E-06"
        ixz="-5.5784E-14"
        iyy="9.473E-05"
        iyz="3.9495E-12"
        izz="9.4694E-05" />
    </inertial>
    <visual>
      <origin
        xyz="0 0 0"
        rpy="0 0 0" />
      <geometry>
        <mesh
          filename="package://k100_description/meshes/k100/o_wheel4_Link.STL" />
      </geometry>
      <material
        name="">
        <color
          rgba="1 1 1 1" />
      </material>
    </visual>
    <collision>
      <origin
        xyz="0 0 0"
        rpy="0 0 0" />
      <geometry>
        <mesh
          filename="package://k100_description/meshes/k100/o_wheel4_Link.STL" />
      </geometry>
    </collision>
  </link>
  <joint
    name="w_body_wheel4_joint"
    type="fixed">
    <origin
      xyz="-0.011114 0.10642 0.126"
      rpy="0 0 0" />
    <parent
      link="base_link" />
    <child
      link="o_wheel4_Link" />
    <axis
      xyz="0 0 1" />
  </joint>
  <link
    name="o_wheel4_1_Link">
    <inertial>
      <origin
        xyz="0.017998 0.00025421 2.6533E-13"
        rpy="0 0 0" />
      <mass
        value="0.086525" />
      <inertia
        ixx="0.00018279"
        ixy="1.2441E-06"
        ixz="-5.5784E-14"
        iyy="9.4724E-05"
        iyz="3.9495E-12"
        izz="9.4688E-05" />
    </inertial>
    <visual>
      <origin
        xyz="0 0 0"
        rpy="0 0 0" />
      <geometry>
        <mesh
          filename="package://k100_description/meshes/k100/o_wheel4_1_Link.STL" />
      </geometry>
      <material
        name="">
        <color
          rgba="1 1 1 1" />
      </material>
    </visual>
    <collision>
      <origin
        xyz="0 0 0"
        rpy="0 0 0" />
      <geometry>
        <mesh
          filename="package://k100_description/meshes/k100/o_wheel4_1_Link.STL" />
      </geometry>
    </collision>
  </link>
  <joint
    name="w_body_wheel4_1_joint"
    type="fixed">
    <origin
      xyz="-0.018281 0.019744 -0.076"
      rpy="0 0 0" />
    <parent
      link="o_wheel4_Link" />
    <child
      link="o_wheel4_1_Link" />
    <axis
      xyz="-0.9999 -0.014123 0" />
  </joint>
  <link
    name="o_wheel5_Link">
    <inertial>
      <origin
        xyz="0.00037442 -0.019996 -0.076"
        rpy="0 0 0" />
      <mass
        value="0.086776" />
      <inertia
        ixx="0.00018279"
        ixy="1.6492E-06"
        ixz="7.3946E-14"
        iyy="9.4743E-05"
        iyz="-3.9492E-12"
        izz="9.4694E-05" />
    </inertial>
    <visual>
      <origin
        xyz="0 0 0"
        rpy="0 0 0" />
      <geometry>
        <mesh
          filename="package://k100_description/meshes/k100/o_wheel5_Link.STL" />
      </geometry>
      <material
        name="">
        <color
          rgba="1 1 1 1" />
      </material>
    </visual>
    <collision>
      <origin
        xyz="0 0 0"
        rpy="0 0 0" />
      <geometry>
        <mesh
          filename="package://k100_description/meshes/k100/o_wheel5_Link.STL" />
      </geometry>
    </collision>
  </link>
  <joint
    name="w_body_wheel5_joint"
    type="fixed">
    <origin
      xyz="-0.0096938 -0.10655 0.126"
      rpy="0 0 0" />
    <parent
      link="base_link" />
    <child
      link="o_wheel5_Link" />
    <axis
      xyz="0 0 1" />
  </joint>
  <link
    name="o_wheel5_1_Link">
    <inertial>
      <origin
        xyz="-0.017997 -0.00033697 2.6533E-13"
        rpy="0 0 0" />
      <mass
        value="0.086525" />
      <inertia
        ixx="0.00018278"
        ixy="1.6491E-06"
        ixz="7.3946E-14"
        iyy="9.4737E-05"
        iyz="-3.9492E-12"
        izz="9.4688E-05" />
    </inertial>
    <visual>
      <origin
        xyz="0 0 0"
        rpy="0 0 0" />
      <geometry>
        <mesh
          filename="package://k100_description/meshes/k100/o_wheel5_1_Link.STL" />
      </geometry>
      <material
        name="">
        <color
          rgba="1 1 1 1" />
      </material>
    </visual>
    <collision>
      <origin
        xyz="0 0 0"
        rpy="0 0 0" />
      <geometry>
        <mesh
          filename="package://k100_description/meshes/k100/o_wheel5_1_Link.STL" />
      </geometry>
    </collision>
  </link>
  <joint
    name="w_body_wheel5_1_joint"
    type="fixed">
    <origin
      xyz="0.018371 -0.01966 -0.076"
      rpy="0 0 0" />
    <parent
      link="o_wheel5_Link" />
    <child
      link="o_wheel5_1_Link" />
    <axis
      xyz="-0.99982 -0.018721 0" />
  </joint>

  <!-- left hand -->



  <joint name="L_base_link_joint" type="fixed">
    <origin xyz="-0.0268 0.005 -0.051" rpy="0 -1.57 -1.57"/>
    <parent link="left_wrist_yaw_link"/>
    <child link="L_hand_base_link"/>
  </joint>
  
  
  <link name="L_hand_base_link">
    <inertial>
      <origin xyz="-0.0545705623202243 0.000958522654081762 -0.00306438373173582" rpy="0 0 0" />
      <mass value="0.0367658161456593" />
      <inertia ixx="1.4186714203091E-05" ixy="2.20190989146005E-06" ixz="5.69534967571968E-07"
               iyy="1.58584689691376E-05" iyz="1.24561852404914E-07" izz="2.47326344757226E-05" />
    </inertial>
    <visual>
      <origin xyz="0 0 0" rpy="0 0 0" />
      <geometry>
        <mesh filename="package://k100_description/meshes/meshes_rohand_lites/L_base_link.STL" />
      </geometry>
      <material name="">
        <color rgba="1 1 1 1" />
      </material>
    </visual>
    <collision>
      <origin xyz="0 0 0" rpy="0 0 0" />
      <geometry>
        <mesh filename="package://k100_description/meshes/meshes_rohand_lites/L_base_link.STL" />
      </geometry>
    </collision>
  </link>

  <link name="L_thumb_proximal_base">
    <inertial>
      <origin xyz="-0.0191689187756942 0.00569828615821762 -0.0016693852678177" rpy="0 0 0" />
      <mass value="0.00195345377003282" />
      <inertia ixx="1.6596112048292E-07" ixy="7.96099037248168E-08" ixz="-1.16578799172214E-08"
               iyy="1.8147620690714E-07" iyz="1.22841840818757E-08" izz="2.16329221955122E-07" />
    </inertial>
    <visual>
      <origin xyz="0 0 0" rpy="0 0 0" />
      <geometry>
        <mesh filename="package://k100_description/meshes/meshes_rohand_lites/L_th_root_link.STL" />
      </geometry>
      <material name="">
        <color rgba="1 1 1 1" />
      </material>
    </visual>
    <collision>
      <origin xyz="0 0 0" rpy="0 0 0" />
      <geometry>
        <mesh filename="package://k100_description/meshes/meshes_rohand_lites/L_th_root_link.STL" />
      </geometry>
    </collision>
  </link>

  <joint name="L_thumb_proximal_yaw_joint" type="revolute">
    <origin xyz="-0.02474 0.01826 -0.019216" rpy="0.0075757 -0.22303 -0.034238" />
    <parent link="L_hand_base_link" />
    <child link="L_thumb_proximal_base" />
    <axis xyz="-1 0 0" />
    <limit lower="-0.1" upper="1.7" effort="1" velocity="2.0" acceleration="5.0" />
  </joint>

  <link name="L_thumb_proximal">
    <inertial>
      <origin xyz="-0.0185320909111181 0.00765760336647799 0.00769895948516403" rpy="0 0 0" />
      <mass value="0.00646398971921865" />
      <inertia ixx="5.69701043131816E-07" ixy="4.94299712334608E-07" ixz="-1.81638866874203E-09"
               iyy="1.67594826700605E-06" iyz="5.54953034071743E-10" izz="2.12783428410059E-06" />
    </inertial>
    <visual>
      <origin xyz="0 0 0" rpy="0 0 0" />
      <geometry>
        <mesh filename="package://k100_description/meshes/meshes_rohand_lites/L_th_proximal_link.STL" />
      </geometry>
      <material name="">
        <color rgba="1 1 1 1" />
      </material>
    </visual>
    <collision>
      <origin xyz="0 0 0" rpy="0 0 0" />
      <geometry>
        <mesh filename="package://k100_description/meshes/meshes_rohand_lites/L_th_proximal_link.STL" />
      </geometry>
    </collision>
  </link>

  <joint name="L_thumb_proximal_pitch_joint" type="revolute">
    <origin xyz="-0.0281675109233723 0.0206776396558676 -0.010414259606288" rpy="-0.00721290411178693 0.000240878411888333 0.0333895499404722" />
    <parent link="L_thumb_proximal_base" />
    <child link="L_thumb_proximal" />
    <axis xyz="0 0 1" />
    <limit lower="0.0" upper="0.4" effort="1" velocity="2.0" acceleration="5.0" />
  </joint>

  <link name="L_thumb_distal">
    <inertial>
      <origin xyz="-0.00904754564000706 0.00635260162604825 0.00681129533264973" rpy="0 0 0" />
      <mass value="0.00464616025042038" />
      <inertia ixx="1.73155668678773E-07" ixy="2.14376248212519E-08" ixz="7.68875433779967E-12"
               iyy="2.35273874670456E-07" iyz="-7.75559011609892E-13" izz="2.09949102085074E-07" />
    </inertial>
    <visual>
      <origin xyz="0 0 0" rpy="0 0 0" />
      <geometry>
        <mesh filename="package://k100_description/meshes/meshes_rohand_lites/L_th_distal_link.STL" />
      </geometry>
      <material name="">
        <color rgba="1 1 1 1" />
      </material>
    </visual>
    <collision>
      <origin xyz="0 0 0" rpy="0 0 0" />
      <geometry>
        <mesh filename="package://k100_description/meshes/meshes_rohand_lites/L_th_distal_link.STL" />
      </geometry>
    </collision>
  </link>

  <joint name="L_thumb_distal_joint" type="revolute">
    <origin xyz="-0.0479097598406365 0.0140073523016571 0.000879436248969738" rpy="0 0 0" />
    <parent link="L_thumb_proximal" />
    <child link="L_thumb_distal" />
    <axis xyz="0 0 1" />
    <limit lower="0" upper="1.2" effort="1" velocity="2.0" acceleration="5.0" />
    <mimic joint="L_thumb_proximal_pitch_joint" multiplier="1.0" offset="0" />
  </joint>

  <link name="L_index_proximal">
    <inertial>
      <origin xyz="-0.01442568349862 0.00682000254611658 0.0074253497626635" rpy="0 0 0" />
      <mass value="0.0020519557292877" />
      <inertia ixx="8.09627570327931E-08" ixy="4.81487284472085E-12" ixz="2.82088862566871E-08"
               iyy="1.89814037862563E-07" iyz="-4.52934896397488E-12" izz="1.96626325307393E-07" />
    </inertial>
    <visual>
      <origin xyz="0 0 0" rpy="0 0 0" />
      <geometry>
        <mesh filename="package://k100_description/meshes/meshes_rohand_lites/L_if_proximal_link.STL" />
      </geometry>
      <material name="">
        <color rgba="1 1 1 1" />
      </material>
    </visual>
    <collision>
      <origin xyz="0 0 0" rpy="0 0 0" />
      <geometry>
        <mesh filename="package://k100_description/meshes/meshes_rohand_lites/L_if_proximal_link.STL" />
      </geometry>
    </collision>
  </link>

<!-- Note: 坐标轴x旋转了180度，暂时改旋转轴向 -->
  <joint name="L_index_proximal_joint" type="revolute">
    <origin xyz="-0.10628 0.036856 -0.0014156" rpy="3.0548 -0.0091764 -0.10508" />
    <parent link="L_hand_base_link" />
    <child link="L_index_proximal" />
    <axis xyz="0 1 0" />
    <limit lower="0" upper="1.2" effort="1" velocity="2.0" acceleration="5.0" />
  </joint>

  <link name="L_index_intermediate">
    <inertial>
      <origin xyz="-0.0123180967294782 -0.00644820912302179 -0.0158568630315067" rpy="0 0 0" />
      <mass value="0.00375858037616174" />
      <inertia ixx="2.63130516542119E-07" ixy="-2.88831462706391E-10" ixz="-1.76316850016938E-07"
               iyy="4.17185892023749E-07" iyz="-3.2422000909467E-10" izz="2.11620474724111E-07" />
    </inertial>
    <visual>
      <origin xyz="0 0 0" rpy="0 0 0" />
      <geometry>
        <mesh filename="package://k100_description/meshes/meshes_rohand_lites/L_if_distal_link.STL" />
      </geometry>
      <material name="">
        <color rgba="1 1 1 1" />
      </material>
    </visual>
    <collision>
      <origin xyz="0 0 0" rpy="0 0 0" />
      <geometry>
        <mesh filename="package://k100_description/meshes/meshes_rohand_lites/L_if_distal_link.STL" />
      </geometry>
    </collision>
  </link>

  <joint name="L_index_intermediate_joint" type="revolute">
    <origin xyz="-0.030939 0.00036803 0.010438" rpy="3.1416 0 0" />
    <parent link="L_index_proximal" />
    <child link="L_index_intermediate" />
    <axis xyz="0 -1 0" />
    <limit lower="0" upper="1.7" effort="1" velocity="2.0" acceleration="5.0" />
    <mimic joint="L_index_proximal_joint" multiplier="1" offset="0" />
  </joint>

  <link name="L_middle_proximal">
    <inertial>
      <origin xyz="-0.0163278718217205 -0.00649192295378876 -0.00963335617479526" rpy="0 0 0" />
      <mass value="0.00248819746655502" />
      <inertia ixx="1.10601992595461E-07" ixy="4.54446489000609E-11" ixz="-6.04962189304454E-08"
               iyy="2.84385954136736E-07" iyz="4.48881092592545E-11" izz="2.73053329475105E-07" />
    </inertial>
    <visual>
      <origin xyz="0 0 0" rpy="0 0 0" />
      <geometry>
        <mesh filename="package://k100_description/meshes/meshes_rohand_lites/L_mf_proximal_link.STL" />
      </geometry>
      <material name="">
        <color rgba="1 1 1 1" />
      </material>
    </visual>
    <collision>
      <origin xyz="0 0 0" rpy="0 0 0" />
      <geometry>
        <mesh filename="package://k100_description/meshes/meshes_rohand_lites/L_mf_proximal_link.STL" />
      </geometry>
    </collision>
  </link>

  <joint name="L_middle_proximal_joint" type="revolute">
    <origin xyz="-0.11015 0.018475 0.0030758" rpy="0.00016503 0 -0.035692" />
    <parent link="L_hand_base_link" />
    <child link="L_middle_proximal" />
    <axis xyz="0 -1 0" />
    <limit lower="0" upper="1.2" effort="1" velocity="2.0" acceleration="5.0" />
  </joint>

  <link name="L_middle_intermediate">
    <inertial>
      <origin xyz="-0.0117763908650274 -0.00644267727147304 -0.0162627454095642" rpy="0 0 0" />
      <mass value="0.00375852857432825" />
      <inertia ixx="2.74945310213643E-07" ixy="-2.76421249981728E-10" ixz="-1.74176296887232E-07"
               iyy="4.17175733749449E-07" iyz="-3.32560853157935E-10" izz="1.99795426402673E-07" />
    </inertial>
    <visual>
      <origin xyz="0 0 0" rpy="0 0 0" />
      <geometry>
        <mesh filename="package://k100_description/meshes/meshes_rohand_lites/L_mf_distal_link.STL" />
      </geometry>
      <material name="">
        <color rgba="1 1 1 1" />
      </material>
    </visual>
    <collision>
      <origin xyz="0 0 0" rpy="0 0 0" />
      <geometry>
        <mesh filename="package://k100_description/meshes/meshes_rohand_lites/L_mf_distal_link.STL" />
      </geometry>
    </collision>
  </link>

  <joint name="L_middle_intermediate_joint" type="revolute">
    <origin xyz="-0.034844 -5.0349E-05 -0.013726" rpy="0.0043984 0.00019026 -0.0075363" />
    <parent link="L_middle_proximal" />
    <child link="L_middle_intermediate" />
    <axis xyz="0 -1 0" />
    <limit lower="0" upper="1.7" effort="1" velocity="2.0" acceleration="5.0" />
    <mimic joint="L_middle_proximal_joint" multiplier="1" offset="0" />
  </joint>

  <link name="L_ring_proximal">
    <inertial>
      <origin xyz="-0.0143563671796693 0.00681998649341342 0.00755846536702151" rpy="0 0 0" />
      <mass value="0.00205195671379772" />
      <inertia ixx="8.14944652395064E-08" ixy="4.70955665732311E-12" ixz="2.92740657063271E-08"
               iyy="1.89813738079667E-07" iyz="-4.49039618473885E-12" izz="1.96094351731653E-07" />
    </inertial>
    <visual>
      <origin xyz="0 0 0" rpy="0 0 0" />
      <geometry>
        <mesh filename="package://k100_description/meshes/meshes_rohand_lites/L_rf_proximal_link.STL" />
      </geometry>
      <material name="">
        <color rgba="1 1 1 1" />
      </material>
    </visual>
    <collision>
      <origin xyz="0 0 0" rpy="0 0 0" />
      <geometry>
        <mesh filename="package://k100_description/meshes/meshes_rohand_lites/L_rf_proximal_link.STL" />
      </geometry>
    </collision>
  </link>

<!-- Note: 坐标轴x旋转了180度，暂时改旋转轴向 -->
  <joint name="L_ring_proximal_joint" type="revolute">
    <origin xyz="-0.10852 0.00052975 0.0024009" rpy="3.1414 0 0.034153" />
    <parent link="L_hand_base_link" />
    <child link="L_ring_proximal" />
    <axis xyz="0 1 0" />
    <limit lower="0" upper="1.2" effort="1" velocity="2.0" acceleration="5.0" />
  </joint>

  <link name="L_ring_intermediate">
    <inertial>
      <origin xyz="-0.0121730609739191 -0.00644820716902625 -0.0159684309110027" rpy="0 0 0" />
      <mass value="0.00375858491630908" />
      <inertia ixx="2.66337255501028E-07" ixy="-2.83461617317305E-10" ixz="-1.75817185730185E-07"
               iyy="4.1718477440461E-07" iyz="-3.26281131146206E-10" izz="2.08412424444304E-07" />
    </inertial>
    <visual>
      <origin xyz="0 0 0" rpy="0 0 0" />
      <geometry>
        <mesh filename="package://k100_description/meshes/meshes_rohand_lites/L_rf_distal_link.STL" />
      </geometry>
      <material name="">
        <color rgba="1 1 1 1" />
      </material>
    </visual>
    <collision>
      <origin xyz="0 0 0" rpy="0 0 0" />
      <geometry>
        <mesh filename="package://k100_description/meshes/meshes_rohand_lites/L_rf_distal_link.STL" />
      </geometry>
    </collision>
  </link>

  <joint name="L_ring_intermediate_joint" type="revolute">
    <origin xyz="-0.030791 0.00036828 0.010696" rpy="-3.1374 0.00011174 0.0076423" />
    <parent link="L_ring_proximal" />
    <child link="L_ring_intermediate" />
    <axis xyz="0 -1 0" />
    <limit lower="0" upper="1.7" effort="1" velocity="2.0" acceleration="5.0" />
    <mimic joint="L_ring_proximal_joint" multiplier="1" offset="0" />
  </joint>

  <link name="L_pinky_proximal">
    <inertial>
      <origin xyz="-0.0126783172515542 -0.00650017197922771 -0.00752321049293611" rpy="0 0 0" />
      <mass value="0.00183703203876047" />
      <inertia ixx="7.28737257765291E-08" ixy="2.35202799697226E-12" ixz="-2.23948893152069E-08"
               iyy="1.40967655054569E-07" iyz="-1.69318267527159E-13" izz="1.47027755964671E-07" />
    </inertial>
    <visual>
      <origin xyz="0 0 0" rpy="0 0 0" />
      <geometry>
        <mesh filename="package://k100_description/meshes/meshes_rohand_lites/L_lf_proximal_link.STL" />
      </geometry>
      <material name="">
        <color rgba="1 1 1 1" />
      </material>
    </visual>
    <collision>
      <origin xyz="0 0 0" rpy="0 0 0" />
      <geometry>
        <mesh filename="package://k100_description/meshes/meshes_rohand_lites/L_lf_proximal_link.STL" />
      </geometry>
    </collision>
  </link>

  <joint name="L_pinky_proximal_joint" type="revolute">
    <origin xyz="-0.10588 -0.01818 0.00065724" rpy="0.08682 -0.0083534 0.09568" />
    <parent link="L_hand_base_link" />
    <child link="L_pinky_proximal" />
    <axis xyz="0 -1 0" />
    <limit lower="0" upper="1.2" effort="1" velocity="2.0" acceleration="5.0" />
  </joint>

  <link name="L_pinky_intermediate">
    <inertial>
      <origin xyz="-0.00651882753544765 -0.00644854835323535 -0.0135103943691352" rpy="0 0 0" />
      <mass value="0.00243586918410262" />
      <inertia ixx="1.19172237830121E-07" ixy="-9.23092755649748E-11" ixz="-4.29645591151488E-08"
               iyy="1.418248902462E-07" iyz="-1.66762811141822E-10" izz="5.41634126707913E-08" />
    </inertial>
    <visual>
      <origin xyz="0 0 0" rpy="0 0 0" />
      <geometry>
        <mesh filename="package://k100_description/meshes/meshes_rohand_lites/L_lf_distal_link.STL" />
      </geometry>
      <material name="">
        <color rgba="1 1 1 1" />
      </material>
    </visual>
    <collision>
      <origin xyz="0 0 0" rpy="0 0 0" />
      <geometry>
        <mesh filename="package://k100_description/meshes/meshes_rohand_lites/L_lf_distal_link.STL" />
      </geometry>
    </collision>
  </link>

  <joint name="L_pinky_intermediate_joint" type="revolute">
    <origin xyz="-0.026922 -5.0837E-05 -0.010935" rpy="0 0 0" />
    <parent link="L_pinky_proximal" />
    <child link="L_pinky_intermediate" />
    <axis xyz="0 -1 0" />
    <limit lower="0" upper="1.7" effort="1" velocity="2.0" acceleration="5.0" />
    <mimic joint="L_pinky_proximal_joint" multiplier="1" offset="0" />
  </joint>


<!-- right hand -->


  <joint name="R_base_link_joint" type="fixed">
    <origin xyz="-0.0268 -0.005 -0.051" rpy="0 -1.57 1.57"/>
    <parent link="right_wrist_yaw_link"/>
    <child link="R_hand_base_link"/>
  </joint>
  

  <link name="R_hand_base_link">
    <inertial>
      <origin xyz="-0.0576030661180955 0.00233560896319593 -0.00133218779459777" rpy="0 0 0" />
      <mass value="0.0493249140792959" />
      <inertia ixx="1.94571823302338E-05" ixy="-1.38729153384568E-06" ixz="1.07807983669446E-06"
               iyy="2.67719341990073E-05" iyz="-3.07356342974464E-07" izz="4.02773132726367E-05" />
    </inertial>
    <visual>
      <origin xyz="0 0 0" rpy="0 0 0" />
      <geometry>
        <mesh filename="package://k100_description/meshes/meshes_rohand_lites/R_base_link.STL" />
      </geometry>
      <material name="">
        <color rgba="1 1 1 1" />
      </material>
    </visual>
    <collision>
      <origin xyz="0 0 0" rpy="0 0 0" />
      <geometry>
        <mesh filename="package://k100_description/meshes/meshes_rohand_lites/R_base_link.STL" />
      </geometry>
    </collision>
  </link>

  <link name="R_thumb_proximal_base">
    <inertial>
      <origin xyz="-0.0191686509683619 -0.00572418793751744 -0.00158132841516827" rpy="0 0 0" />
      <mass value="0.00195350966248874" />
      <inertia ixx="1.65972225377993E-07" ixy="-7.97825490860689E-08" ixz="-1.04261831309922E-08"
               iyy="1.8111092952085E-07" iyz="-1.1733271461248E-08" izz="2.16718599283951E-07" />
    </inertial>
    <visual>
      <origin xyz="0 0 0" rpy="0 0 0" />
      <geometry>
        <mesh filename="package://k100_description/meshes/meshes_rohand_lites/R_th_root_link.STL" />
      </geometry>
      <material name="">
        <color rgba="1 1 1 1" />
      </material>
    </visual>
    <collision>
      <origin xyz="0 0 0" rpy="0 0 0" />
      <geometry>
        <mesh filename="package://k100_description/meshes/meshes_rohand_lites/R_th_root_link.STL" />
      </geometry>
    </collision>
  </link>

  <joint name="R_thumb_proximal_yaw_joint" type="revolute">
    <origin xyz="-0.025954 -0.01648 -0.019186" rpy="0.0078865 -0.22303 -0.035641" />
    <parent link="R_hand_base_link" />
    <child link="R_thumb_proximal_base" />
    <axis xyz="1 0 0" />
    <limit lower="-0.1" upper="1.7" effort="1" velocity="2.0" acceleration="5.0" />
  </joint>

  <link name="R_thumb_proximal">
    <inertial>
      <origin xyz="-0.0190126820702974 -0.00637807841543053 0.00769785866417869" rpy="0 0 0" />
      <mass value="0.00646388849033333" />
      <inertia ixx="5.07687345462868E-07" ixy="-4.14559349698037E-07" ixz="-1.8674365709823E-09"
               iyy="1.73768654791953E-06" iyz="-4.20029512218484E-10" izz="2.12756394178572E-06" />
    </inertial>
    <visual>
      <origin xyz="0 0 0" rpy="0 0 0" />
      <geometry>
        <mesh filename="package://k100_description/meshes/meshes_rohand_lites/R_th_proximal_link.STL" />
      </geometry>
      <material name="">
        <color rgba="1 1 1 1" />
      </material>
    </visual>
    <collision>
      <origin xyz="0 0 0" rpy="0 0 0" />
      <geometry>
        <mesh filename="package://k100_description/meshes/meshes_rohand_lites/R_th_proximal_link.STL" />
      </geometry>
    </collision>
  </link>

  <joint name="R_thumb_proximal_pitch_joint" type="revolute">
    <origin xyz="-0.028168 -0.020837 -0.010094" rpy="-0.0082402 0.00028649 0.034758" />
    <parent link="R_thumb_proximal_base" />
    <child link="R_thumb_proximal" />
    <axis xyz="0 0 -1" />
    <limit lower="0.0" upper="0.4" effort="1" velocity="2.0" acceleration="5.0" />
  </joint>

  <link name="R_thumb_distal">
    <inertial>
      <origin xyz="-0.0094593690473327 -0.0057218027674614 0.0068108911892128" rpy="0 0 0" />
      <mass value="0.00464616536496131" />
      <inertia ixx="1.70526363877279E-07" ixy="-1.70171405060127E-08" ixz="-3.06434125828904E-12"
               iyy="2.37897880292055E-07" iyz="1.31087369006255E-12" izz="2.09937364304614E-07" />
    </inertial>
    <visual>
      <origin xyz="0 0 0" rpy="0 0 0" />
      <geometry>
        <mesh filename="package://k100_description/meshes/meshes_rohand_lites/R_th_distal_link.STL" />
      </geometry>
      <material name="">
        <color rgba="1 1 1 1" />
      </material>
    </visual>
    <collision>
      <origin xyz="0 0 0" rpy="0 0 0" />
      <geometry>
        <mesh filename="package://k100_description/meshes/meshes_rohand_lites/R_th_distal_link.STL" />
      </geometry>
    </collision>
  </link>

  <joint name="R_thumb_distal_joint" type="revolute">
    <origin xyz="-0.048752 -0.010712 0.00087944" rpy="0 0 0" />
    <parent link="R_thumb_proximal" />
    <child link="R_thumb_distal" />
    <axis xyz="0 0 -1" />
    <limit lower="0" upper="1.2" effort="1" velocity="2.0" acceleration="5.0" />
    <mimic joint="R_thumb_proximal_pitch_joint" multiplier="1.0" offset="0" />
  </joint>

  <link name="R_index_proximal">
    <inertial>
      <origin xyz="-0.0143787205756178 0.0068202042615699 -0.00751216413311831" rpy="0 0 0" />
      <mass value="0.00205183706838826" />
      <inertia ixx="8.13016698160853E-08" ixy="1.51094306482205E-11" ixz="-2.88949821390807E-08"
               iyy="1.89783171251403E-07" iyz="4.65572959060812E-12" izz="1.96251769923446E-07" />
    </inertial>
    <visual>
      <origin xyz="0 0 0" rpy="0 0 0" />
      <geometry>
        <mesh filename="package://k100_description/meshes/meshes_rohand_lites/R_if_proximal_link.STL" />
      </geometry>
      <material name="">
        <color rgba="1 1 1 1" />
      </material>
    </visual>
    <collision>
      <origin xyz="0 0 0" rpy="0 0 0" />
      <geometry>
        <mesh filename="package://k100_description/meshes/meshes_rohand_lites/R_if_proximal_link.STL" />
      </geometry>
    </collision>
  </link>

  <joint name="R_index_proximal_joint" type="revolute">
    <origin xyz="-0.10859 -0.029338 -0.0013861" rpy="0.086779 -0.00311 0.035733" />
    <parent link="R_hand_base_link" />
    <child link="R_index_proximal" />
    <axis xyz="0 -1 0" />
    <limit lower="0" upper="1.2" effort="1" velocity="2.0" acceleration="5.0" />
  </joint>

  <link name="R_index_intermediate">
    <inertial>
      <origin xyz="-0.012222373112902 0.00644744577874212 -0.0159308052491082" rpy="0 0 0" />
      <mass value="0.00375868071914677" />
      <inertia ixx="2.6526744005835E-07" ixy="2.68139132185787E-10" ixz="-1.76013365071367E-07"
               iyy="4.17225025361236E-07" iyz="3.16739936806118E-10" izz="2.09518827365182E-07" />
    </inertial>
    <visual>
      <origin xyz="0 0 0" rpy="0 0 0" />
      <geometry>
        <mesh filename="package://k100_description/meshes/meshes_rohand_lites/R_if_distal_link.STL" />
      </geometry>
      <material name="">
        <color rgba="1 1 1 1" />
      </material>
    </visual>
    <collision>
      <origin xyz="0 0 0" rpy="0 0 0" />
      <geometry>
        <mesh filename="package://k100_description/meshes/meshes_rohand_lites/R_if_distal_link.STL" />
      </geometry>
    </collision>
  </link>

  <joint name="R_index_intermediate_joint" type="revolute">
    <origin xyz="-0.030875 0.00036803 -0.010625" rpy="0 0 0" />
    <parent link="R_index_proximal" />
    <child link="R_index_intermediate" />
    <axis xyz="0 -1 0" />
    <limit lower="0" upper="1.7" effort="1" velocity="2.0" acceleration="5.0" />
    <mimic joint="R_index_proximal_joint" multiplier="1" offset="0" />
  </joint>

  <link name="R_middle_proximal">
    <inertial>
      <origin xyz="-0.016329453759154 0.00649226533975397 -0.00963384586033489" rpy="0 0 0" />
      <mass value="0.00248843296883051" />
      <inertia ixx="1.10610510723197E-07" ixy="-5.89496390356217E-11" ixz="-6.05126652788143E-08"
               iyy="2.8446139484122E-07" iyz="-4.21063735821963E-11" izz="2.7312514865437E-07" />
    </inertial>
    <visual>
      <origin xyz="0 0 0" rpy="0 0 0" />
      <geometry>
        <mesh filename="package://k100_description/meshes/meshes_rohand_lites/R_mf_proximal_link.STL" />
      </geometry>
      <material name="">
        <color rgba="1 1 1 1" />
      </material>
    </visual>
    <collision>
      <origin xyz="0 0 0" rpy="0 0 0" />
      <geometry>
        <mesh filename="package://k100_description/meshes/meshes_rohand_lites/R_mf_proximal_link.STL" />
      </geometry>
    </collision>
  </link>

  <joint name="R_middle_proximal_joint" type="revolute">
    <origin xyz="-0.111168350336371 -0.0107315849401363 0.00310533319557881" rpy="-0.000165024105879644 0 -0.0341875332667528" />
    <parent link="R_hand_base_link" />
    <child link="R_middle_proximal" />
    <axis xyz="0 -1 0" />
    <limit lower="0" upper="1.2" effort="1" velocity="2.0" acceleration="5.0" />
  </joint>

  <link name="R_middle_intermediate">
    <inertial>
      <origin xyz="-0.0117807102189178 0.00644198393359627 -0.0162599790204698" rpy="0 0 0" />
      <mass value="0.00375867884267013" />
      <inertia ixx="2.74876926237726E-07" ixy="2.59466981378291E-10" ixz="-1.7421907947615E-07"
               iyy="4.1722285891413E-07" iyz="3.23406111565757E-10" izz="1.99906902685593E-07" />
    </inertial>
    <visual>
      <origin xyz="0 0 0" rpy="0 0 0" />
      <geometry>
        <mesh filename="package://k100_description/meshes/meshes_rohand_lites/R_mf_distal_link.STL" />
      </geometry>
      <material name="">
        <color rgba="1 1 1 1" />
      </material>
    </visual>
    <collision>
      <origin xyz="0 0 0" rpy="0 0 0" />
      <geometry>
        <mesh filename="package://k100_description/meshes/meshes_rohand_lites/R_mf_distal_link.STL" />
      </geometry>
    </collision>
  </link>

  <joint name="R_middle_intermediate_joint" type="revolute">
    <origin xyz="-0.0348440227740655 5.03497035553302E-05 -0.0137271073982339" rpy="-0.00439882751506536 -0.000117257737364924 0.00753742768873965" />
    <parent link="R_middle_proximal" />
    <child link="R_middle_intermediate" />
    <axis xyz="0 -1 0" />
    <limit lower="0" upper="1.7" effort="1" velocity="2.0" acceleration="5.0" />
    <mimic joint="R_middle_proximal_joint" multiplier="1" offset="0" />
  </joint>

  <link name="R_ring_proximal">
    <inertial>
      <origin xyz="-0.0143549280434906 0.00682023657911832 -0.00755778479766486" rpy="0 0 0" />
      <mass value="0.00205187294843744" />
      <inertia ixx="8.14868585707663E-08" ixy="1.41861573407726E-11" ixz="-2.9259876910324E-08"
               iyy="1.89786107772236E-07" iyz="4.79988274178486E-12" izz="1.960702878707E-07" />
    </inertial>
    <visual>
      <origin xyz="0 0 0" rpy="0 0 0" />
      <geometry>
        <mesh filename="package://k100_description/meshes/meshes_rohand_lites/R_rf_proximal_link.STL" />
      </geometry>
      <material name="">
        <color rgba="1 1 1 1" />
      </material>
    </visual>
    <collision>
      <origin xyz="0 0 0" rpy="0 0 0" />
      <geometry>
        <mesh filename="package://k100_description/meshes/meshes_rohand_lites/R_rf_proximal_link.STL" />
      </geometry>
    </collision>
  </link>

  <joint name="R_ring_proximal_joint" type="revolute">
    <origin xyz="-0.10829 0.007056 0.0024304" rpy="0.00015789 1.6485E-05 -0.10403" />
    <parent link="R_hand_base_link" />
    <child link="R_ring_proximal" />
    <axis xyz="0 -1 0" />
    <limit lower="0" upper="1.2" effort="1" velocity="2.0" acceleration="5.0" />
  </joint>

  <link name="R_ring_intermediate">
    <inertial>
      <origin xyz="-0.0121787543720058 0.0064475580290749 -0.0159643969071744" rpy="0 0 0" />
      <mass value="0.00375873422510174" />
      <inertia ixx="2.66234188468105E-07" ixy="2.66619623996111E-10" ixz="-1.75861376428997E-07"
               iyy="4.17230114265725E-07" iyz="3.17193421265111E-10" izz="2.0855875648093E-07" />
    </inertial>
    <visual>
      <origin xyz="0 0 0" rpy="0 0 0" />
      <geometry>
        <mesh filename="package://k100_description/meshes/meshes_rohand_lites/R_rf_distal_link.STL" />
      </geometry>
      <material name="">
        <color rgba="1 1 1 1" />
      </material>
    </visual>
    <collision>
      <origin xyz="0 0 0" rpy="0 0 0" />
      <geometry>
        <mesh filename="package://k100_description/meshes/meshes_rohand_lites/R_rf_distal_link.STL" />
      </geometry>
    </collision>
  </link>

  <joint name="R_ring_intermediate_joint" type="revolute">
    <origin xyz="-0.030791 0.00036828 -0.010696" rpy="-0.0042136 -0.0004074 0.0076437" />
    <parent link="R_ring_proximal" />
    <child link="R_ring_intermediate" />
    <axis xyz="0 -1 0" />
    <limit lower="0" upper="1.7" effort="1" velocity="2.0" acceleration="5.0" />
    <mimic joint="R_ring_proximal_joint" multiplier="1" offset="0" />
  </joint>

  <link name="R_pinky_proximal">
    <inertial>
      <origin xyz="-0.0127241110356107 0.00649957990170523 -0.00744483846071534" rpy="0 0 0" />
      <mass value="0.00183686407359195" />
      <inertia ixx="7.25936420936618E-08" ixy="1.26029064472353E-12" ixz="-2.19325321953627E-08"
               iyy="1.40948330406022E-07" iyz="-3.97609924901949E-13" izz="1.47282231216297E-07" />
    </inertial>
    <visual>
      <origin xyz="0 0 0" rpy="0 0 0" />
      <geometry>
        <mesh filename="package://k100_description/meshes/meshes_rohand_lites/R_lf_proximal_link.STL" />
      </geometry>
      <material name="">
        <color rgba="1 1 1 1" />
      </material>
    </visual>
    <collision>
      <origin xyz="0 0 0" rpy="0 0 0" />
      <geometry>
        <mesh filename="package://k100_description/meshes/meshes_rohand_lites/R_lf_proximal_link.STL" />
      </geometry>
    </collision>
  </link>

  <joint name="R_pinky_proximal_joint" type="revolute">
    <origin xyz="-0.10436 0.025536 0.00068678" rpy="-0.086826 -0.014497 -0.16502" />
    <parent link="R_hand_base_link" />
    <child link="R_pinky_proximal" />
    <axis xyz="0 -1 0" />
    <limit lower="0" upper="1.2" effort="1" velocity="2.0" acceleration="5.0" />
  </joint>

  <link name="R_pinky_intermediate">
    <inertial>
      <origin xyz="-0.00660185291159945 0.00644841570480648 -0.0134694736191499" rpy="0 0 0" />
      <mass value="0.00243556509111398" />
      <inertia ixx="1.18626211477515E-07" ixy="9.45828083556239E-11" ixz="-4.33572574582032E-08"
               iyy="1.41808396396924E-07" iyz="1.67029567238108E-10" izz="5.46901618733586E-08" />
    </inertial>
    <visual>
      <origin xyz="0 0 0" rpy="0 0 0" />
      <geometry>
        <mesh filename="package://k100_description/meshes/meshes_rohand_lites/R_lf_distal_link.STL" />
      </geometry>
      <material name="">
        <color rgba="1 1 1 1" />
      </material>
    </visual>
    <collision>
      <origin xyz="0 0 0" rpy="0 0 0" />
      <geometry>
        <mesh filename="package://k100_description/meshes/meshes_rohand_lites/R_lf_distal_link.STL" />
      </geometry>
    </collision>
  </link>

  <joint name="R_pinky_intermediate_joint" type="revolute">
    <origin xyz="-0.026989 5.0837E-05 -0.010769" rpy="0 0 0" />
    <parent link="R_pinky_proximal" />
    <child link="R_pinky_intermediate" />
    <axis xyz="0 -1 0" />
    <limit lower="0" upper="1.7" effort="1" velocity="2.0" acceleration="5.0" />
    <mimic joint="R_pinky_proximal_joint" multiplier="1" offset="0" />
  </joint>
</robot>