<?xml version="1.0" encoding="utf-8"?>

<robot name="x100_with_rohand_lites">

  <link name="base_link">
    <visual>
      <origin xyz="0 0 0" rpy="0 0 0" />
      <geometry>
        <mesh filename="package://x100_description/mesh/meshes_x100/base_link.STL" />
      </geometry>
      <material name="">
        <color rgba="0.752941176470588 0.752941176470588 0.752941176470588 1" />
      </material>
    </visual>
    <collision>
      <origin xyz="0 0 0" rpy="0 0 0" />
      <geometry>
        <mesh filename="package://x100_description/mesh/meshes_x100/base_link.STL" />
      </geometry>
    </collision>
  </link>
  <!-- <link name="floor_link">
    <inertial>
      <origin xyz="0 0 0" rpy="0 0 0" />
      <mass value="0.0001" />
      <inertia ixx="9.6e-06" ixy="0.0" ixz="0.0" iyy="9.6e-06" iyz="0.0" izz="9.6e-06" />
    </inertial>
    <visual>
    <origin xyz="0 0 0" rpy="0 0 0" />
      <geometry>
        <sphere radius="0.05"/>
      </geometry>
      <material name="">
        <color rgba="0.1 0.4 0.1 1" />
      </material>
    </visual>
  </link>
  <joint name="floor_joint" type="fixed" dont_collapse="true">
    <origin xyz="0.0 0.0 -0.18" rpy="0 0 0" />
    <parent link="base_link" />
    <child link="floor_link" />
  </joint> -->

  <link name="AGV_yaw_left_link">
    <inertial>
      <origin xyz="-2.20127873151732E-08 -0.0308114801670985 -0.0545910530423015" rpy="0 0 0" />
      <mass value="0.245281608487464" />
      <inertia ixx="0.000503753735624281" ixy="4.10082374702644E-10" ixz="1.937854081737E-10" iyy="0.000417106600465128" iyz="-0.000178452953060026" izz="0.000165582706992007" />
    </inertial>
    <visual>
      <origin xyz="0 0 0" rpy="0 0 0" />
      <geometry>
        <mesh filename="package://x100_description/mesh/meshes_x100/AGV_yaw_left_link.STL" />
      </geometry>
      <material name="">
        <color rgba="0.862745098039216 0.549019607843137 0.545098039215686 1" />
      </material>
    </visual>
    <collision>
      <origin xyz="0 0 0" rpy="0 0 0" />
      <geometry>
        <mesh filename="package://x100_description/mesh/meshes_x100/AGV_yaw_left_link.STL" />
      </geometry>
    </collision>
  </link>
  <joint name="AGV_yaw_left_joint" type="fixed">
    <origin xyz="0.23812 0.16 0.0025" rpy="0 0 0" />
    <parent link="base_link" />
    <child link="AGV_yaw_left_link" />
  </joint>
  <link name="AGV_move_left_link">
    <inertial>
      <origin xyz="1.3125436945649E-06 0.000669578114391972 -6.87249532782541E-07" rpy="0 0 0" />
      <mass value="1.69111524658837" />
      <inertia ixx="0.00346749257557015" ixy="1.24371544208643E-07" ixz="3.99749317493181E-08" iyy="0.00664551858147923" iyz="-6.96591659784327E-08" izz="0.00346752087830564" />
    </inertial>
    <visual>
      <origin xyz="0 0 0" rpy="0 0 0" />
      <geometry>
        <mesh filename="package://x100_description/mesh/meshes_x100/AGV_move_left_link.STL" />
      </geometry>
      <material name="">
        <color rgba="0.752941176470588 0.752941176470588 0.752941176470588 1" />
      </material>
    </visual>
    <collision>
      <origin xyz="0 0 0" rpy="0 0 0" />
      <geometry>
        <mesh filename="package://x100_description/mesh/meshes_x100/AGV_move_left_link.STL" />
      </geometry>
    </collision>
  </link>
  <joint name="AGV_move_left_joint" type="fixed">
    <origin xyz="0 0.003 -0.113" rpy="0 0 0" />
    <parent link="AGV_yaw_left_link" />
    <child link="AGV_move_left_link" />
  </joint>
  <link name="AGV_yaw_right_link">
    <inertial>
      <origin xyz="2.21773192865538E-08 0.0308107310557345 -0.0545906819417435" rpy="0 0 0" />
      <mass value="0.245284643073316" />
      <inertia ixx="0.000503766633726159" ixy="1.98479609326591E-10" ixz="-2.27302245478898E-10" iyy="0.000417108589011739" iyz="0.000178458897580688" izz="0.000165591414689412" />
    </inertial>
    <visual>
      <origin xyz="0 0 0" rpy="0 0 0" />
      <geometry>
        <mesh filename="package://x100_description/mesh/meshes_x100/AGV_yaw_right_link.STL" />
      </geometry>
      <material name="">
        <color rgba="0.862745098039216 0.549019607843137 0.545098039215686 1" />
      </material>
    </visual>
    <collision>
      <origin xyz="0 0 0" rpy="0 0 0" />
      <geometry>
        <mesh filename="package://x100_description/mesh/meshes_x100/AGV_yaw_right_link.STL" />
      </geometry>
    </collision>
  </link>
  <joint name="AGV_yaw_right_joint" type="fixed">
    <origin xyz="0.23812 -0.16 0.0025" rpy="0 0 0" />
    <parent link="base_link" />
    <child link="AGV_yaw_right_link" />
  </joint>
  <link name="AGV_move_right_link">
    <inertial>
      <origin xyz="3.60312727376577E-07 -0.000669578114401742 -1.4472475801941E-06" rpy="0 0 0" />
      <mass value="1.69111524658912" />
      <inertia ixx="0.00346753700500628" ixy="-3.9833827483275E-08" ixz="2.96899812584189E-08" iyy="0.00664551858147842" iyz="1.36855657825959E-07" izz="0.0034674764488687" />
    </inertial>
    <visual>
      <origin xyz="0 0 0" rpy="0 0 0" />
      <geometry>
        <mesh filename="package://x100_description/mesh/meshes_x100/AGV_move_right_link.STL" />
      </geometry>
      <material name="">
        <color rgba="0.752941176470588 0.752941176470588 0.752941176470588 1" />
      </material>
    </visual>
    <collision>
      <origin xyz="0 0 0" rpy="0 0 0" />
      <geometry>
        <mesh filename="package://x100_description/mesh/meshes_x100/AGV_move_right_link.STL" />
      </geometry>
    </collision>
  </link>
  <joint name="AGV_move_right_joint" type="fixed">
    <origin xyz="0 -0.003 -0.113" rpy="0 0 0" />
    <parent link="AGV_yaw_right_link" />
    <child link="AGV_move_right_link" />
  </joint>
  <link name="AGV_yaw_behind_link">
    <inertial>
      <origin xyz="-2.20127576722184E-08 -0.030811480167095 -0.0545910530423015" rpy="0 0 0" />
      <mass value="0.245281608487463" />
      <inertia ixx="0.00050375373562428" ixy="4.10082557039496E-10" ixz="1.93785730569901E-10" iyy="0.000417106600465126" iyz="-0.000178452953060025" izz="0.000165582706992006" />
    </inertial>
    <visual>
      <origin xyz="0 0 0" rpy="0 0 0" />
      <geometry>
        <mesh filename="package://x100_description/mesh/meshes_x100/AGV_yaw_behind_link.STL" />
      </geometry>
      <material name="">
        <color rgba="0.862745098039216 0.549019607843137 0.545098039215686 1" />
      </material>
    </visual>
    <collision>
      <origin xyz="0 0 0" rpy="0 0 0" />
      <geometry>
        <mesh filename="package://x100_description/mesh/meshes_x100/AGV_yaw_behind_link.STL" />
      </geometry>
    </collision>
  </link>
  <joint name="AGV_yaw_behind_joint" type="fixed">
    <origin xyz="-0.23812 0 0.0025" rpy="0 0 0" />
    <parent link="base_link" />
    <child link="AGV_yaw_behind_link" />
  </joint>
  <link name="AGV_move_behind_link">
    <inertial>
      <origin xyz="-6.00844289960767E-07 0.000669578114403075 -1.36504100609058E-06" rpy="0 0 0" />
      <mass value="1.69111524658924" />
      <inertia ixx="0.0034675253215695" ixy="-6.24954542992371E-08" ixz="-3.81116268341795E-08" iyy="0.00664551858147844" iyz="-1.28103564388489E-07" izz="0.0034674881323055" />
    </inertial>
    <visual>
      <origin xyz="0 0 0" rpy="0 0 0" />
      <geometry>
        <mesh filename="package://x100_description/mesh/meshes_x100/AGV_move_behind_link.STL" />
      </geometry>
      <material name="">
        <color rgba="0.752941176470588 0.752941176470588 0.752941176470588 1" />
      </material>
    </visual>
    <collision>
      <origin xyz="0 0 0" rpy="0 0 0" />
      <geometry>
        <mesh filename="package://x100_description/mesh/meshes_x100/AGV_move_behind_link.STL" />
      </geometry>
    </collision>
  </link>
  <joint name="AGV_move_behind_joint" type="fixed">
    <origin xyz="0 0.003 -0.113" rpy="0 0 0" />
    <parent link="AGV_yaw_behind_link" />
    <child link="AGV_move_behind_link" />
  </joint>
  <link name="waist_base_link">
    <inertial>
      <origin xyz="2.09526840322383E-13 0.00265003390392317 0.0524998502660636" rpy="0 0 0" />
      <mass value="1.49396139233906" />
      <inertia ixx="0.00496258543415969" ixy="-1.13293216718744E-15" ixz="1.04959160440269E-14" iyy="0.00631292060029423" iyz="-0.000129244440401722" izz="0.00402504155232433" />
    </inertial>
    <visual>
      <origin xyz="0 0 0" rpy="0 0 0" />
      <geometry>
        <mesh filename="package://x100_description/mesh/meshes_x100/waist_base_link.STL" />
      </geometry>
      <material name="">
        <color rgba="0.752941176470588 0.752941176470588 0.752941176470588 1" />
      </material>
    </visual>
    <collision>
      <origin xyz="0 0 0" rpy="0 0 0" />
      <geometry>
        <mesh filename="package://x100_description/mesh/meshes_x100/waist_base_link.STL" />
      </geometry>
    </collision>
  </link>
  <joint name="waist_base_joint" type="fixed">
    <origin xyz="-0.033123 0 0" rpy="0 0 0" />
    <parent link="base_link" />
    <child link="waist_base_link" />
    <axis xyz="0 0 0" />
  </joint>
  <link name="waist_pitch_lower_link">
    <inertial>
      <origin xyz="2.96984659087229E-15 -0.0141552313426734 0.124999999999997" rpy="0 0 0" />
      <mass value="2.27314251059694" />
      <inertia ixx="0.0131039481721402" ixy="-4.53990923117907E-19" ixz="-2.62714093901037E-15" iyy="0.0162447317794585" iyz="1.61157118440538E-18" izz="0.00317648335707216" />
    </inertial>
    <visual>
      <origin xyz="0 0 0" rpy="0 0 0" />
      <geometry>
        <mesh filename="package://x100_description/mesh/meshes_x100/waist_pitch_lower_link.STL" />
      </geometry>
      <material name="">
        <color rgba="0.752941176470588 0.752941176470588 0.752941176470588 1" />
      </material>
    </visual>
    <collision>
      <origin xyz="0 0 0" rpy="0 0 0" />
      <geometry>
        <mesh filename="package://x100_description/mesh/meshes_x100/waist_pitch_lower_link.STL" />
      </geometry>
    </collision>
  </link>
  <joint name="waist_pitch_lower_joint" type="fixed">
    <origin xyz="0 0 0.083" rpy="0 0 0" />
    <parent link="waist_base_link" />
    <child link="waist_pitch_lower_link" />
    <axis xyz="0 1 0" />
    <limit lower="-0.26" upper="1.58" effort="20" velocity="1.5" acceleration="3.0" />
  </joint>
  <link name="waist_pitch_middle_link">
    <inertial>
      <origin xyz="5.09321188148226E-07 -0.000209304781470008 0.101942053324824" rpy="0 0 0" />
      <mass value="5.43354669139441" />
      <inertia ixx="0.013154147426128" ixy="-9.19180998800125E-08" ixz="1.36829596153063E-07" iyy="0.0148906837969918" iyz="-3.11776079023088E-06" izz="0.00923980974272249" />
    </inertial>
    <visual>
      <origin xyz="0 0 0" rpy="0 0 0" />
      <geometry>
        <mesh filename="package://x100_description/mesh/meshes_x100/waist_pitch_middle_link.STL" />
      </geometry>
      <material name="">
        <color rgba="0.752941176470588 0.752941176470588 0.752941176470588 1" />
      </material>
    </visual>
    <collision>
      <origin xyz="0 0 0" rpy="0 0 0" />
      <geometry>
        <mesh filename="package://x100_description/mesh/meshes_x100/waist_pitch_middle_link.STL" />
      </geometry>
    </collision>
  </link>
  <joint name="waist_pitch_middle_joint" type="fixed">
    <origin xyz="0 0 0.25" rpy="0 0 0" />
    <parent link="waist_pitch_lower_link" />
    <child link="waist_pitch_middle_link" />
    <axis xyz="0 1 0" />
    <limit lower="-2.62" upper="1.58" effort="20" velocity="1.5" acceleration="3.0" />
  </joint>
  <link name="waist_pitch_upper_link">
    <inertial>
      <origin xyz="-0.000145504008478729 0.00493260548813689 0.0485823662178412" rpy="0 0 0" />
      <mass value="5.38731120662336" />
      <inertia ixx="0.01" ixy="0" ixz="0" iyy="0.01" iyz="0" izz="0.01" />
    </inertial>
    <visual>
      <origin xyz="0 0 0" rpy="0 0 0" />
      <geometry>
        <mesh filename="package://x100_description/mesh/meshes_x100/waist_pitch_upper_link.STL" />
      </geometry>
      <material name="">
        <color rgba="0.752941176470588 0.752941176470588 0.752941176470588 1" />
      </material>
    </visual>
    <collision>
      <origin xyz="0 0 0" rpy="0 0 0" />
      <geometry>
        <mesh filename="package://x100_description/mesh/meshes_x100/waist_pitch_upper_link.STL" />
      </geometry>
    </collision>
  </link>
  <joint name="waist_pitch_upper_joint" type="fixed">
    <origin xyz="0 0 0.34" rpy="0 0 0" />
    <parent link="waist_pitch_middle_link" />
    <child link="waist_pitch_upper_link" />
    <axis xyz="0 1 0" />
    <limit lower="-1.75" upper="1.75" effort="20" velocity="1.5" acceleration="3.0" />
  </joint>
  <link name="torso_link">
    <inertial>
      <origin xyz="4.33469348894155E-05 -6.59120500852507E-09 0.193501192535377" rpy="0 0 0" />
      <mass value="9.64909156541158" />
      <inertia ixx="0.041134238011689" ixy="2.43191640635395E-11" ixz="1.74260275070872E-07" iyy="0.0404085995567576" iyz="-4.83252761210217E-08" izz="0.00912370613854259" />
    </inertial>
    <visual>
      <origin xyz="0 0 0" rpy="0 0 0" />
      <geometry>
        <mesh filename="package://x100_description/mesh/meshes_x100/torso_link.STL" />
      </geometry>
      <material name="">
        <color rgba="0.752941176470588 0.752941176470588 0.752941176470588 1" />
      </material>
    </visual>
    <collision>
      <origin xyz="0 0 0" rpy="0 0 0" />
      <geometry>
        <mesh filename="package://x100_description/mesh/meshes_x100/torso_link.STL" />
      </geometry>
    </collision>
  </link>
  <joint name="torso_joint" type="fixed">
    <origin xyz="0 0 0.1921" rpy="0 0 0" />
    <parent link="waist_pitch_upper_link" />
    <child link="torso_link" />
  </joint>
  <link name="head_yaw_link">
    <inertial>
      <origin xyz="0.0275842176371693 0.00217561201075011 0.0500852030582835" rpy="0 0 0" />
      <mass value="0.627068603775774" />
      <inertia ixx="0.000290069729963355" ixy="6.30683945111433E-19" ixz="4.73629825279625E-06" iyy="0.00029461278597458" iyz="-6.11635629331064E-20" izz="0.000305874917451081" />
    </inertial>
    <visual>
      <origin xyz="0 0 0" rpy="0 0 0" />
      <geometry>
        <mesh filename="package://x100_description/mesh/meshes_x100/head_yaw_link.STL" />
      </geometry>
      <material name="">
        <color rgba="0.752941176470588 0.752941176470588 0.752941176470588 1" />
      </material>
    </visual>
    <collision>
      <origin xyz="0 0 0" rpy="0 0 0" />
      <geometry>
        <mesh filename="package://x100_description/mesh/meshes_x100/head_yaw_link.STL" />
      </geometry>
    </collision>
  </link>
  <joint name="head_yaw_joint" type="fixed">
    <origin xyz="0 0 0.372" rpy="0 0 0" />
    <parent link="torso_link" />
    <child link="head_yaw_link" />
  </joint>
  <link name="head_pitch_link">
    <inertial>
      <origin xyz="-0.00267989529824948 -0.000252755812069182 0.0657034221106612" rpy="0 0 0" />
      <mass value="0.3980723351526" />
      <inertia ixx="0.000428232869052577" ixy="-5.48580750729812E-07" ixz="3.45478422004712E-05" iyy="0.000400329046827211" iyz="-1.1368304582303E-06" izz="0.000294783298626689" />
    </inertial>
    <visual>
      <origin xyz="0 0 0" rpy="0 0 0" />
      <geometry>
        <mesh filename="package://x100_description/mesh/meshes_x100/head_pitch_link.STL" />
      </geometry>
      <material name="">
        <color rgba="0.752941176470588 0.752941176470588 0.752941176470588 1" />
      </material>
    </visual>
    <collision>
      <origin xyz="0 0 0" rpy="0 0 0" />
      <geometry>
        <mesh filename="package://x100_description/mesh/meshes_x100/head_pitch_link.STL" />
      </geometry>
    </collision>
  </link>
  <joint name="head_pitch_joint" type="fixed">
    <origin xyz="0.035 0 0.059" rpy="0 0 0" />
    <parent link="head_yaw_link" />
    <child link="head_pitch_link" />
  </joint>
  <link name="right_shoulder_pitch_link">
    <inertial>
      <origin xyz="-0.00367675986297206 -0.0542463290286199 2.58812120668139E-06" rpy="0 0 0" />
      <mass value="0.848985464266451" />
      <inertia ixx="0.00101435274555589" ixy="-6.52592313780756E-06" ixz="-2.67015667645939E-09" iyy="0.000703710291045494" iyz="-5.55773825089475E-08" izz="0.000777317035946405" />
    </inertial>
    <visual>
      <origin xyz="0 0 0" rpy="0 0 0" />
      <geometry>
        <mesh filename="package://x100_description/mesh/meshes_x100/right_shoulder_pitch_link.STL" />
      </geometry>
      <material name="">
        <color rgba="0.752941176470588 0.752941176470588 0.752941176470588 1" />
      </material>
    </visual>
    <collision>
      <origin xyz="0 0 0" rpy="0 0 0" />
      <geometry>
        <mesh filename="package://x100_description/mesh/meshes_x100/right_shoulder_pitch_link.STL" />
      </geometry>
    </collision>
  </link>
  <joint name="right_shoulder_pitch_joint" type="revolute">
    <origin xyz="0 -0.1476 0.2615" rpy="0 0 0" />
    <parent link="torso_link" />
    <child link="right_shoulder_pitch_link" />
    <axis xyz="0 1 0" />
    <limit lower="-2.97" upper="2.97" effort="10" velocity="1.5" acceleration="3.0" />
  </joint>
  <link name="right_shoulder_roll_link">
    <inertial>
      <origin xyz="-0.00238241924076597 -1.78570058793348E-05 -0.0802603066944463" rpy="0 0 0" />
      <mass value="0.933711800407855" />
      <inertia ixx="0.00119865742149175" ixy="-6.83313664569594E-09" ixz="7.82145055807086E-05" iyy="0.00144607852532589" iyz="-7.44656033059175E-08" izz="0.000879151973489193" />
    </inertial>
    <visual>
      <origin xyz="0 0 0" rpy="0 0 0" />
      <geometry>
        <mesh filename="package://x100_description/mesh/meshes_x100/right_shoulder_roll_link.STL" />
      </geometry>
      <material name="">
        <color rgba="0.752941176470588 0.752941176470588 0.752941176470588 1" />
      </material>
    </visual>
    <collision>
      <origin xyz="0 0 0" rpy="0 0 0" />
      <geometry>
        <mesh filename="package://x100_description/mesh/meshes_x100/right_shoulder_roll_link.STL" />
      </geometry>
    </collision>
  </link>
  <joint name="right_shoulder_roll_joint" type="revolute">
    <origin xyz="0 -0.062 0" rpy="0 0 0" />
    <parent link="right_shoulder_pitch_link" />
    <child link="right_shoulder_roll_link" />
    <axis xyz="-1 0 0" />
    <limit lower="-0.1" upper="3.23" effort="10" velocity="1.5" acceleration="3.0" />
  </joint>
  <link name="right_shoulder_yaw_link">
    <inertial>
      <origin xyz="0.0189918826968868 0.00594635691085862 -0.085403773275452" rpy="0 0 0" />
      <mass value="0.434423544379079" />
      <inertia ixx="0.000408182306507528" ixy="2.16892318900535E-06" ixz="6.02795239356358E-05" iyy="0.000586839962048929" iyz="-3.71823771866569E-06" izz="0.000256135143070958" />
    </inertial>
    <visual>
      <origin xyz="0 0 0" rpy="0 0 0" />
      <geometry>
        <mesh filename="package://x100_description/mesh/meshes_x100/right_shoulder_yaw_link.STL" />
      </geometry>
      <material name="">
        <color rgba="0.752941176470588 0.752941176470588 0.752941176470588 1" />
      </material>
    </visual>
    <collision>
      <origin xyz="0 0 0" rpy="0 0 0" />
      <geometry>
        <mesh filename="package://x100_description/mesh/meshes_x100/right_shoulder_yaw_link.STL" />
      </geometry>
    </collision>
  </link>
  <joint name="right_shoulder_yaw_joint" type="revolute">
    <origin xyz="0 0 -0.1226" rpy="0 0 0" />
    <parent link="right_shoulder_roll_link" />
    <child link="right_shoulder_yaw_link" />
    <axis xyz="0 0 1" />
    <limit lower="-2.97" upper="2.97" effort="10" velocity="1.5" acceleration="3.0" />
  </joint>
  <link name="right_elbow_link">
    <inertial>
      <origin xyz="-0.019682834096401 0.00614384016014732 -0.0604081681694035" rpy="0 0 0" />
      <mass value="0.58376847457249" />
      <inertia ixx="0.000342571414101762" ixy="-3.1037867572582E-07" ixz="-3.94693000973267E-05" iyy="0.000378503966929614" iyz="1.06104636163208E-06" izz="0.000235756043947694" />
    </inertial>
    <visual>
      <origin xyz="0 0 0" rpy="0 0 0" />
      <geometry>
        <mesh filename="package://x100_description/mesh/meshes_x100/right_elbow_link.STL" />
      </geometry>
      <material name="">
        <color rgba="0.752941176470588 0.752941176470588 0.752941176470588 1" />
      </material>
    </visual>
    <collision>
      <origin xyz="0 0 0" rpy="0 0 0" />
      <geometry>
        <mesh filename="package://x100_description/mesh/meshes_x100/right_elbow_link.STL" />
      </geometry>
    </collision>
  </link>
  <joint name="right_elbow_joint" type="revolute">
    <origin xyz="0.024 0 -0.0974" rpy="0 0 0" />
    <parent link="right_shoulder_yaw_link" />
    <child link="right_elbow_link" />
    <axis xyz="0 1 0" />
    <limit lower="-2.93" upper="0" effort="10" velocity="1.5" acceleration="3.0" />
  </joint>
  <link name="right_wrist_roll_link">
    <inertial>
      <origin xyz="6.33741171502528E-06 0.00322995701196074 -0.0870317620723344" rpy="0 0 0" />
      <mass value="0.50628831282003" />
      <inertia ixx="0.000647960138543212" ixy="2.39225855360338E-08" ixz="3.85045712031872E-08" iyy="0.000771891906211482" iyz="1.41932992276395E-06" izz="0.000159980806279759" />
    </inertial>
    <visual>
      <origin xyz="0 0 0" rpy="0 0 0" />
      <geometry>
        <mesh filename="package://x100_description/mesh/meshes_x100/right_wrist_roll_link.STL" />
      </geometry>
      <material name="">
        <color rgba="0.752941176470588 0.752941176470588 0.752941176470588 1" />
      </material>
    </visual>
    <collision>
      <origin xyz="0 0 0" rpy="0 0 0" />
      <geometry>
        <mesh filename="package://x100_description/mesh/meshes_x100/right_wrist_roll_link.STL" />
      </geometry>
    </collision>
  </link>
  <joint name="right_wrist_roll_joint" type="revolute">
    <origin xyz="-0.024 0 -0.1071" rpy="0 0 0" />
    <parent link="right_elbow_link" />
    <child link="right_wrist_roll_link" />
    <axis xyz="0 0 1" />
    <limit lower="-2.97" upper="2.97" effort="10" velocity="1.5" acceleration="3.0" />
  </joint>
  <link name="right_wrist_pitch_link">
    <inertial>
      <origin xyz="0.00692425572694247 -0.000314175932120797 -0.0445846340712968" rpy="0 0 0" />
      <mass value="0.267350739628338" />
      <inertia ixx="0.000151332196130114" ixy="-7.35240847816505E-07" ixz="-1.245851354345E-06" iyy="9.72372255189296E-05" iyz="-1.69762837430636E-05" izz="7.60269950821654E-05" />
    </inertial>
    <visual>
      <origin xyz="0 0 0" rpy="0 0 0" />
      <geometry>
        <mesh filename="package://x100_description/mesh/meshes_x100/right_wrist_pitch_link.STL" />
      </geometry>
      <material name="">
        <color rgba="0.752941176470588 0.752941176470588 0.752941176470588 1" />
      </material>
    </visual>
    <collision>
      <origin xyz="0 0 0" rpy="0 0 0" />
      <geometry>
        <mesh filename="package://x100_description/mesh/meshes_x100/right_wrist_pitch_link.STL" />
      </geometry>
    </collision>
  </link>
  <joint name="right_wrist_pitch_joint" type="revolute">
    <origin xyz="0 -5E-05 -0.1389" rpy="0 0 0" />
    <parent link="right_wrist_roll_link" />
    <child link="right_wrist_pitch_link" />
    <axis xyz="0 1 0" />
    <limit lower="-1.83" upper="1.83" effort="10" velocity="1.5" acceleration="3.0" />
  </joint>
  <link name="right_wrist_yaw_link">
    <inertial>
      <origin xyz="-0.00113349353882937 0.000182092284429197 -0.0313472200645663" rpy="0 0 0" />
      <mass value="0.111035645621271" />
      <inertia ixx="3.38338924623756E-05" ixy="1.24787404345728E-12" ixz="-6.25606490323498E-06" iyy="4.01749527734222E-05" iyz="1.39960038102222E-07" izz="4.39077979186707E-05" />
    </inertial>
    <visual>
      <origin xyz="0 0 0" rpy="0 0 0" />
      <geometry>
        <mesh filename="package://x100_description/mesh/meshes_x100/right_wrist_yaw_link.STL" />
      </geometry>
      <material name="">
        <color rgba="0.752941176470588 0.752941176470588 0.752941176470588 1" />
      </material>
    </visual>
    <collision>
      <origin xyz="0 0 0" rpy="0 0 0" />
      <geometry>
        <mesh filename="package://x100_description/mesh/meshes_x100/right_wrist_yaw_link.STL" />
      </geometry>
    </collision>
  </link>
  <joint name="right_wrist_yaw_joint" type="revolute">
    <origin xyz="-0.00235 5E-05 -0.054" rpy="0 0 0" />
    <parent link="right_wrist_pitch_link" />
    <child link="right_wrist_yaw_link" />
    <axis xyz="1 0 0" />
    <limit lower="-1.57" upper="1.57" effort="10" velocity="1.5" acceleration="3.0" />
  </joint>
  <link name="left_shoulder_pitch_link">
    <inertial>
      <origin xyz="0.00367675986297346 0.0542463290286198 2.58812120934593E-06" rpy="0 0 0" />
      <mass value="0.848985464266447" />
      <inertia ixx="0.00101435274555589" ixy="-6.52592313780649E-06" ixz="2.67015667694552E-09" iyy="0.000703710291045487" iyz="5.55773825079637E-08" izz="0.000777317035946401" />
    </inertial>
    <visual>
      <origin xyz="0 0 0" rpy="0 0 0" />
      <geometry>
        <mesh filename="package://x100_description/mesh/meshes_x100/left_shoulder_pitch_link.STL" />
      </geometry>
      <material name="">
        <color rgba="0.752941176470588 0.752941176470588 0.752941176470588 1" />
      </material>
    </visual>
    <collision>
      <origin xyz="0 0 0" rpy="0 0 0" />
      <geometry>
        <mesh filename="package://x100_description/mesh/meshes_x100/left_shoulder_pitch_link.STL" />
      </geometry>
    </collision>
  </link>
  <joint name="left_shoulder_pitch_joint" type="revolute">
    <origin xyz="0 0.1476 0.2615" rpy="0 0 0" />
    <parent link="torso_link" />
    <child link="left_shoulder_pitch_link" />
    <axis xyz="0 1 0" />
    <limit lower="-2.97" upper="2.97" effort="10" velocity="1.5" acceleration="3.0" />
  </joint>
  <link name="left_shoulder_roll_link">
    <inertial>
      <origin xyz="0.00238241927309023 1.78571130299288E-05 -0.0802603069606076" rpy="0 0 0" />
      <mass value="0.933711806710216" />
      <inertia ixx="0.00119865742150416" ixy="-6.8331452308249E-09" ixz="-7.82145056337858E-05" iyy="0.00144607852706074" iyz="7.44654864441209E-08" izz="0.000879151975219498" />
    </inertial>
    <visual>
      <origin xyz="0 0 0" rpy="0 0 0" />
      <geometry>
        <mesh filename="package://x100_description/mesh/meshes_x100/left_shoulder_roll_link.STL" />
      </geometry>
      <material name="">
        <color rgba="0.752941176470588 0.752941176470588 0.752941176470588 1" />
      </material>
    </visual>
    <collision>
      <origin xyz="0 0 0" rpy="0 0 0" />
      <geometry>
        <mesh filename="package://x100_description/mesh/meshes_x100/left_shoulder_roll_link.STL" />
      </geometry>
    </collision>
  </link>
  <joint name="left_shoulder_roll_joint" type="revolute">
    <origin xyz="0 0.062 0" rpy="0 0 0" />
    <parent link="left_shoulder_pitch_link" />
    <child link="left_shoulder_roll_link" />
    <axis xyz="1 0 0" />
    <limit lower="-0.1" upper="3.23" effort="10" velocity="1.5" acceleration="3.0" />
  </joint>
  <link name="left_shoulder_yaw_link">
    <inertial>
      <origin xyz="0.0189918829302687 0.00594635656039608 -0.0854037727048453" rpy="0 0 0" />
      <mass value="0.43442353862093" />
      <inertia ixx="0.000408182305701526" ixy="2.16892334074131E-06" ixz="6.02795231435692E-05" iyy="0.000586839960456974" iyz="-3.71823751035217E-06" izz="0.000256135142270292" />
    </inertial>
    <visual>
      <origin xyz="0 0 0" rpy="0 0 0" />
      <geometry>
        <mesh filename="package://x100_description/mesh/meshes_x100/left_shoulder_yaw_link.STL" />
      </geometry>
      <material name="">
        <color rgba="0.752941176470588 0.752941176470588 0.752941176470588 1" />
      </material>
    </visual>
    <collision>
      <origin xyz="0 0 0" rpy="0 0 0" />
      <geometry>
        <mesh filename="package://x100_description/mesh/meshes_x100/left_shoulder_yaw_link.STL" />
      </geometry>
    </collision>
  </link>
  <joint name="left_shoulder_yaw_joint" type="revolute">
    <origin xyz="0 0 -0.1226" rpy="0 0 0" />
    <parent link="left_shoulder_roll_link" />
    <child link="left_shoulder_yaw_link" />
    <axis xyz="0 0 1" />
    <limit lower="-2.97" upper="2.97" effort="10" velocity="1.5" acceleration="3.0" />
  </joint>
  <link name="left_elbow_link">
    <inertial>
      <origin xyz="-0.0196828338193763 0.0061438404656593 -0.0604081675829152" rpy="0 0 0" />
      <mass value="0.583768481365716" />
      <inertia ixx="0.000342571334166883" ixy="-3.103786399656E-07" ixz="-3.94692997000234E-05" iyy="0.000378503572130911" iyz="1.0610462595637E-06" izz="0.000235755565732729" />
    </inertial>
    <visual>
      <origin xyz="0 0 0" rpy="0 0 0" />
      <geometry>
        <mesh filename="package://x100_description/mesh/meshes_x100/left_elbow_link.STL" />
      </geometry>
      <material name="">
        <color rgba="0.752941176470588 0.752941176470588 0.752941176470588 1" />
      </material>
    </visual>
    <collision>
      <origin xyz="0 0 0" rpy="0 0 0" />
      <geometry>
        <mesh filename="package://x100_description/mesh/meshes_x100/left_elbow_link.STL" />
      </geometry>
    </collision>
  </link>
  <joint name="left_elbow_joint" type="revolute">
    <origin xyz="0.024 0 -0.0974" rpy="0 0 0" />
    <parent link="left_shoulder_yaw_link" />
    <child link="left_elbow_link" />
    <axis xyz="0 1 0" />
    <limit lower="-2.93" upper="0" effort="10" velocity="1.5" acceleration="3.0" />
  </joint>
  <link name="left_wrist_roll_link">
    <inertial>
      <origin xyz="6.33741555387118E-06 0.00322995701444354 -0.0870317620689255" rpy="0 0 0" />
      <mass value="0.506288312825421" />
      <inertia ixx="0.000647960138446467" ixy="2.39225898712566E-08" ixz="3.85046178915717E-08" iyy="0.00077189190611103" iyz="1.41932991467436E-06" izz="0.00015998080628097" />
    </inertial>
    <visual>
      <origin xyz="0 0 0" rpy="0 0 0" />
      <geometry>
        <mesh filename="package://x100_description/mesh/meshes_x100/left_wrist_roll_link.STL" />
      </geometry>
      <material name="">
        <color rgba="0.752941176470588 0.752941176470588 0.752941176470588 1" />
      </material>
    </visual>
    <collision>
      <origin xyz="0 0 0" rpy="0 0 0" />
      <geometry>
        <mesh filename="package://x100_description/mesh/meshes_x100/left_wrist_roll_link.STL" />
      </geometry>
    </collision>
  </link>
  <joint name="left_wrist_roll_joint" type="revolute">
    <origin xyz="-0.024 0 -0.1071" rpy="0 0 0" />
    <parent link="left_elbow_link" />
    <child link="left_wrist_roll_link" />
    <axis xyz="0 0 1" />
    <limit lower="-2.97" upper="2.97" effort="10" velocity="1.5" acceleration="3.0" />
  </joint>
  <link name="left_wrist_pitch_link">
    <inertial>
      <origin xyz="0.0069242557337307 -0.000314175944311268 -0.0445846339748781" rpy="0 0 0" />
      <mass value="0.267350738654715" />
      <inertia ixx="0.000151332195823477" ixy="-7.35240854432935E-07" ixz="-1.24585131717319E-06" iyy="9.72372252181943E-05" iyz="-1.69762837953283E-05" izz="7.60269950666379E-05" />
    </inertial>
    <visual>
      <origin xyz="0 0 0" rpy="0 0 0" />
      <geometry>
        <mesh filename="package://x100_description/mesh/meshes_x100/left_wrist_pitch_link.STL" />
      </geometry>
      <material name="">
        <color rgba="0.752941176470588 0.752941176470588 0.752941176470588 1" />
      </material>
    </visual>
    <collision>
      <origin xyz="0 0 0" rpy="0 0 0" />
      <geometry>
        <mesh filename="package://x100_description/mesh/meshes_x100/left_wrist_pitch_link.STL" />
      </geometry>
    </collision>
  </link>
  <joint name="left_wrist_pitch_joint" type="revolute">
    <origin xyz="0 -5E-05 -0.1389" rpy="0 0 0" />
    <parent link="left_wrist_roll_link" />
    <child link="left_wrist_pitch_link" />
    <axis xyz="0 1 0" />
    <limit lower="-1.83" upper="1.83" effort="10" velocity="1.5" acceleration="3.0" />
  </joint>
  <link name="left_wrist_yaw_link">
    <inertial>
      <origin xyz="-0.00348349377502552 0.000182092284442215 -0.0313472200645634" rpy="0 0 0" />
      <mass value="0.111035645621272" />
      <inertia ixx="3.38338924623758E-05" ixy="1.24787410720316E-12" ixz="-6.25606490323477E-06" iyy="4.01749527734219E-05" iyz="1.39960038102022E-07" izz="4.39077979186708E-05" />
    </inertial>
    <visual>
      <origin xyz="0 0 0" rpy="0 0 0" />
      <geometry>
        <mesh filename="package://x100_description/mesh/meshes_x100/left_wrist_yaw_link.STL" />
      </geometry>
      <material name="">
        <color rgba="0.752941176470588 0.752941176470588 0.752941176470588 1" />
      </material>
    </visual>
    <collision>
      <origin xyz="0 0 0" rpy="0 0 0" />
      <geometry>
        <mesh filename="package://x100_description/mesh/meshes_x100/left_wrist_yaw_link.STL" />
      </geometry>
    </collision>
  </link>
  <joint name="left_wrist_yaw_joint" type="revolute">
    <origin xyz="0 5E-05 -0.054" rpy="0 0 0" />
    <parent link="left_wrist_pitch_link" />
    <child link="left_wrist_yaw_link" />
    <axis xyz="1 0 0" />
    <limit lower="-1.57" upper="1.57" effort="10" velocity="1.5" acceleration="3.0" />
  </joint>


<!-- left hand -->



  <joint name="L_base_link_joint" type="fixed">
    <origin xyz="0 0 -0.054" rpy="0 -1.57 -1.57"/>
    <parent link="left_wrist_yaw_link"/>
    <child link="L_hand_base_link"/>
  </joint>
  
  
  <link name="L_hand_base_link">
    <inertial>
      <origin xyz="-0.0545705623202243 0.000958522654081762 -0.00306438373173582" rpy="0 0 0" />
      <mass value="0.0367658161456593" />
      <inertia ixx="1.4186714203091E-05" ixy="2.20190989146005E-06" ixz="5.69534967571968E-07"
               iyy="1.58584689691376E-05" iyz="1.24561852404914E-07" izz="2.47326344757226E-05" />
    </inertial>
    <visual>
      <origin xyz="0 0 0" rpy="0 0 0" />
      <geometry>
        <mesh filename="package://x100_description/mesh/meshes_rohand_lites/L_base_link.STL" />
      </geometry>
      <material name="">
        <color rgba="1 1 1 1" />
      </material>
    </visual>
    <collision>
      <origin xyz="0 0 0" rpy="0 0 0" />
      <geometry>
        <mesh filename="package://x100_description/mesh/meshes_rohand_lites/L_base_link.STL" />
      </geometry>
    </collision>
  </link>

  <link name="L_thumb_proximal_base">
    <inertial>
      <origin xyz="-0.0191689187756942 0.00569828615821762 -0.0016693852678177" rpy="0 0 0" />
      <mass value="0.00195345377003282" />
      <inertia ixx="1.6596112048292E-07" ixy="7.96099037248168E-08" ixz="-1.16578799172214E-08"
               iyy="1.8147620690714E-07" iyz="1.22841840818757E-08" izz="2.16329221955122E-07" />
    </inertial>
    <visual>
      <origin xyz="0 0 0" rpy="0 0 0" />
      <geometry>
        <mesh filename="package://x100_description/mesh/meshes_rohand_lites/L_th_root_link.STL" />
      </geometry>
      <material name="">
        <color rgba="1 1 1 1" />
      </material>
    </visual>
    <collision>
      <origin xyz="0 0 0" rpy="0 0 0" />
      <geometry>
        <mesh filename="package://x100_description/mesh/meshes_rohand_lites/L_th_root_link.STL" />
      </geometry>
    </collision>
  </link>

  <joint name="L_thumb_proximal_yaw_joint" type="revolute">
    <origin xyz="-0.02474 0.01826 -0.019216" rpy="0.0075757 -0.22303 -0.034238" />
    <parent link="L_hand_base_link" />
    <child link="L_thumb_proximal_base" />
    <axis xyz="-1 0 0" />
    <limit lower="-0.1" upper="1.7" effort="1" velocity="2.0" acceleration="5.0" />
  </joint>

  <link name="L_thumb_proximal">
    <inertial>
      <origin xyz="-0.0185320909111181 0.00765760336647799 0.00769895948516403" rpy="0 0 0" />
      <mass value="0.00646398971921865" />
      <inertia ixx="5.69701043131816E-07" ixy="4.94299712334608E-07" ixz="-1.81638866874203E-09"
               iyy="1.67594826700605E-06" iyz="5.54953034071743E-10" izz="2.12783428410059E-06" />
    </inertial>
    <visual>
      <origin xyz="0 0 0" rpy="0 0 0" />
      <geometry>
        <mesh filename="package://x100_description/mesh/meshes_rohand_lites/L_th_proximal_link.STL" />
      </geometry>
      <material name="">
        <color rgba="1 1 1 1" />
      </material>
    </visual>
    <collision>
      <origin xyz="0 0 0" rpy="0 0 0" />
      <geometry>
        <mesh filename="package://x100_description/mesh/meshes_rohand_lites/L_th_proximal_link.STL" />
      </geometry>
    </collision>
  </link>

  <joint name="L_thumb_proximal_pitch_joint" type="revolute">
    <origin xyz="-0.0281675109233723 0.0206776396558676 -0.010414259606288" rpy="-0.00721290411178693 0.000240878411888333 0.0333895499404722" />
    <parent link="L_thumb_proximal_base" />
    <child link="L_thumb_proximal" />
    <axis xyz="0 0 1" />
    <limit lower="0.0" upper="0.4" effort="1" velocity="2.0" acceleration="5.0" />
  </joint>

  <link name="L_thumb_distal">
    <inertial>
      <origin xyz="-0.00904754564000706 0.00635260162604825 0.00681129533264973" rpy="0 0 0" />
      <mass value="0.00464616025042038" />
      <inertia ixx="1.73155668678773E-07" ixy="2.14376248212519E-08" ixz="7.68875433779967E-12"
               iyy="2.35273874670456E-07" iyz="-7.75559011609892E-13" izz="2.09949102085074E-07" />
    </inertial>
    <visual>
      <origin xyz="0 0 0" rpy="0 0 0" />
      <geometry>
        <mesh filename="package://x100_description/mesh/meshes_rohand_lites/L_th_distal_link.STL" />
      </geometry>
      <material name="">
        <color rgba="1 1 1 1" />
      </material>
    </visual>
    <collision>
      <origin xyz="0 0 0" rpy="0 0 0" />
      <geometry>
        <mesh filename="package://x100_description/mesh/meshes_rohand_lites/L_th_distal_link.STL" />
      </geometry>
    </collision>
  </link>

  <joint name="L_thumb_distal_joint" type="revolute">
    <origin xyz="-0.0479097598406365 0.0140073523016571 0.000879436248969738" rpy="0 0 0" />
    <parent link="L_thumb_proximal" />
    <child link="L_thumb_distal" />
    <axis xyz="0 0 1" />
    <limit lower="0" upper="1.2" effort="1" velocity="2.0" acceleration="5.0" />
    <mimic joint="L_thumb_proximal_pitch_joint" multiplier="1.0" offset="0" />
  </joint>

  <link name="L_index_proximal">
    <inertial>
      <origin xyz="-0.01442568349862 0.00682000254611658 0.0074253497626635" rpy="0 0 0" />
      <mass value="0.0020519557292877" />
      <inertia ixx="8.09627570327931E-08" ixy="4.81487284472085E-12" ixz="2.82088862566871E-08"
               iyy="1.89814037862563E-07" iyz="-4.52934896397488E-12" izz="1.96626325307393E-07" />
    </inertial>
    <visual>
      <origin xyz="0 0 0" rpy="0 0 0" />
      <geometry>
        <mesh filename="package://x100_description/mesh/meshes_rohand_lites/L_if_proximal_link.STL" />
      </geometry>
      <material name="">
        <color rgba="1 1 1 1" />
      </material>
    </visual>
    <collision>
      <origin xyz="0 0 0" rpy="0 0 0" />
      <geometry>
        <mesh filename="package://x100_description/mesh/meshes_rohand_lites/L_if_proximal_link.STL" />
      </geometry>
    </collision>
  </link>

<!-- Note: 坐标轴x旋转了180度，暂时改旋转轴向 -->
  <joint name="L_index_proximal_joint" type="revolute">
    <origin xyz="-0.10628 0.036856 -0.0014156" rpy="3.0548 -0.0091764 -0.10508" />
    <parent link="L_hand_base_link" />
    <child link="L_index_proximal" />
    <axis xyz="0 1 0" />
    <limit lower="0" upper="1.2" effort="1" velocity="2.0" acceleration="5.0" />
  </joint>

  <link name="L_index_intermediate">
    <inertial>
      <origin xyz="-0.0123180967294782 -0.00644820912302179 -0.0158568630315067" rpy="0 0 0" />
      <mass value="0.00375858037616174" />
      <inertia ixx="2.63130516542119E-07" ixy="-2.88831462706391E-10" ixz="-1.76316850016938E-07"
               iyy="4.17185892023749E-07" iyz="-3.2422000909467E-10" izz="2.11620474724111E-07" />
    </inertial>
    <visual>
      <origin xyz="0 0 0" rpy="0 0 0" />
      <geometry>
        <mesh filename="package://x100_description/mesh/meshes_rohand_lites/L_if_distal_link.STL" />
      </geometry>
      <material name="">
        <color rgba="1 1 1 1" />
      </material>
    </visual>
    <collision>
      <origin xyz="0 0 0" rpy="0 0 0" />
      <geometry>
        <mesh filename="package://x100_description/mesh/meshes_rohand_lites/L_if_distal_link.STL" />
      </geometry>
    </collision>
  </link>

  <joint name="L_index_intermediate_joint" type="revolute">
    <origin xyz="-0.030939 0.00036803 0.010438" rpy="3.1416 0 0" />
    <parent link="L_index_proximal" />
    <child link="L_index_intermediate" />
    <axis xyz="0 -1 0" />
    <limit lower="0" upper="1.7" effort="1" velocity="2.0" acceleration="5.0" />
    <mimic joint="L_index_proximal_joint" multiplier="1" offset="0" />
  </joint>

  <link name="L_middle_proximal">
    <inertial>
      <origin xyz="-0.0163278718217205 -0.00649192295378876 -0.00963335617479526" rpy="0 0 0" />
      <mass value="0.00248819746655502" />
      <inertia ixx="1.10601992595461E-07" ixy="4.54446489000609E-11" ixz="-6.04962189304454E-08"
               iyy="2.84385954136736E-07" iyz="4.48881092592545E-11" izz="2.73053329475105E-07" />
    </inertial>
    <visual>
      <origin xyz="0 0 0" rpy="0 0 0" />
      <geometry>
        <mesh filename="package://x100_description/mesh/meshes_rohand_lites/L_mf_proximal_link.STL" />
      </geometry>
      <material name="">
        <color rgba="1 1 1 1" />
      </material>
    </visual>
    <collision>
      <origin xyz="0 0 0" rpy="0 0 0" />
      <geometry>
        <mesh filename="package://x100_description/mesh/meshes_rohand_lites/L_mf_proximal_link.STL" />
      </geometry>
    </collision>
  </link>

  <joint name="L_middle_proximal_joint" type="revolute">
    <origin xyz="-0.11015 0.018475 0.0030758" rpy="0.00016503 0 -0.035692" />
    <parent link="L_hand_base_link" />
    <child link="L_middle_proximal" />
    <axis xyz="0 -1 0" />
    <limit lower="0" upper="1.2" effort="1" velocity="2.0" acceleration="5.0" />
  </joint>

  <link name="L_middle_intermediate">
    <inertial>
      <origin xyz="-0.0117763908650274 -0.00644267727147304 -0.0162627454095642" rpy="0 0 0" />
      <mass value="0.00375852857432825" />
      <inertia ixx="2.74945310213643E-07" ixy="-2.76421249981728E-10" ixz="-1.74176296887232E-07"
               iyy="4.17175733749449E-07" iyz="-3.32560853157935E-10" izz="1.99795426402673E-07" />
    </inertial>
    <visual>
      <origin xyz="0 0 0" rpy="0 0 0" />
      <geometry>
        <mesh filename="package://x100_description/mesh/meshes_rohand_lites/L_mf_distal_link.STL" />
      </geometry>
      <material name="">
        <color rgba="1 1 1 1" />
      </material>
    </visual>
    <collision>
      <origin xyz="0 0 0" rpy="0 0 0" />
      <geometry>
        <mesh filename="package://x100_description/mesh/meshes_rohand_lites/L_mf_distal_link.STL" />
      </geometry>
    </collision>
  </link>

  <joint name="L_middle_intermediate_joint" type="revolute">
    <origin xyz="-0.034844 -5.0349E-05 -0.013726" rpy="0.0043984 0.00019026 -0.0075363" />
    <parent link="L_middle_proximal" />
    <child link="L_middle_intermediate" />
    <axis xyz="0 -1 0" />
    <limit lower="0" upper="1.7" effort="1" velocity="2.0" acceleration="5.0" />
    <mimic joint="L_middle_proximal_joint" multiplier="1" offset="0" />
  </joint>

  <link name="L_ring_proximal">
    <inertial>
      <origin xyz="-0.0143563671796693 0.00681998649341342 0.00755846536702151" rpy="0 0 0" />
      <mass value="0.00205195671379772" />
      <inertia ixx="8.14944652395064E-08" ixy="4.70955665732311E-12" ixz="2.92740657063271E-08"
               iyy="1.89813738079667E-07" iyz="-4.49039618473885E-12" izz="1.96094351731653E-07" />
    </inertial>
    <visual>
      <origin xyz="0 0 0" rpy="0 0 0" />
      <geometry>
        <mesh filename="package://x100_description/mesh/meshes_rohand_lites/L_rf_proximal_link.STL" />
      </geometry>
      <material name="">
        <color rgba="1 1 1 1" />
      </material>
    </visual>
    <collision>
      <origin xyz="0 0 0" rpy="0 0 0" />
      <geometry>
        <mesh filename="package://x100_description/mesh/meshes_rohand_lites/L_rf_proximal_link.STL" />
      </geometry>
    </collision>
  </link>

<!-- Note: 坐标轴x旋转了180度，暂时改旋转轴向 -->
  <joint name="L_ring_proximal_joint" type="revolute">
    <origin xyz="-0.10852 0.00052975 0.0024009" rpy="3.1414 0 0.034153" />
    <parent link="L_hand_base_link" />
    <child link="L_ring_proximal" />
    <axis xyz="0 1 0" />
    <limit lower="0" upper="1.2" effort="1" velocity="2.0" acceleration="5.0" />
  </joint>

  <link name="L_ring_intermediate">
    <inertial>
      <origin xyz="-0.0121730609739191 -0.00644820716902625 -0.0159684309110027" rpy="0 0 0" />
      <mass value="0.00375858491630908" />
      <inertia ixx="2.66337255501028E-07" ixy="-2.83461617317305E-10" ixz="-1.75817185730185E-07"
               iyy="4.1718477440461E-07" iyz="-3.26281131146206E-10" izz="2.08412424444304E-07" />
    </inertial>
    <visual>
      <origin xyz="0 0 0" rpy="0 0 0" />
      <geometry>
        <mesh filename="package://x100_description/mesh/meshes_rohand_lites/L_rf_distal_link.STL" />
      </geometry>
      <material name="">
        <color rgba="1 1 1 1" />
      </material>
    </visual>
    <collision>
      <origin xyz="0 0 0" rpy="0 0 0" />
      <geometry>
        <mesh filename="package://x100_description/mesh/meshes_rohand_lites/L_rf_distal_link.STL" />
      </geometry>
    </collision>
  </link>

  <joint name="L_ring_intermediate_joint" type="revolute">
    <origin xyz="-0.030791 0.00036828 0.010696" rpy="-3.1374 0.00011174 0.0076423" />
    <parent link="L_ring_proximal" />
    <child link="L_ring_intermediate" />
    <axis xyz="0 -1 0" />
    <limit lower="0" upper="1.7" effort="1" velocity="2.0" acceleration="5.0" />
    <mimic joint="L_ring_proximal_joint" multiplier="1" offset="0" />
  </joint>

  <link name="L_pinky_proximal">
    <inertial>
      <origin xyz="-0.0126783172515542 -0.00650017197922771 -0.00752321049293611" rpy="0 0 0" />
      <mass value="0.00183703203876047" />
      <inertia ixx="7.28737257765291E-08" ixy="2.35202799697226E-12" ixz="-2.23948893152069E-08"
               iyy="1.40967655054569E-07" iyz="-1.69318267527159E-13" izz="1.47027755964671E-07" />
    </inertial>
    <visual>
      <origin xyz="0 0 0" rpy="0 0 0" />
      <geometry>
        <mesh filename="package://x100_description/mesh/meshes_rohand_lites/L_lf_proximal_link.STL" />
      </geometry>
      <material name="">
        <color rgba="1 1 1 1" />
      </material>
    </visual>
    <collision>
      <origin xyz="0 0 0" rpy="0 0 0" />
      <geometry>
        <mesh filename="package://x100_description/mesh/meshes_rohand_lites/L_lf_proximal_link.STL" />
      </geometry>
    </collision>
  </link>

  <joint name="L_pinky_proximal_joint" type="revolute">
    <origin xyz="-0.10588 -0.01818 0.00065724" rpy="0.08682 -0.0083534 0.09568" />
    <parent link="L_hand_base_link" />
    <child link="L_pinky_proximal" />
    <axis xyz="0 -1 0" />
    <limit lower="0" upper="1.2" effort="1" velocity="2.0" acceleration="5.0" />
  </joint>

  <link name="L_pinky_intermediate">
    <inertial>
      <origin xyz="-0.00651882753544765 -0.00644854835323535 -0.0135103943691352" rpy="0 0 0" />
      <mass value="0.00243586918410262" />
      <inertia ixx="1.19172237830121E-07" ixy="-9.23092755649748E-11" ixz="-4.29645591151488E-08"
               iyy="1.418248902462E-07" iyz="-1.66762811141822E-10" izz="5.41634126707913E-08" />
    </inertial>
    <visual>
      <origin xyz="0 0 0" rpy="0 0 0" />
      <geometry>
        <mesh filename="package://x100_description/mesh/meshes_rohand_lites/L_lf_distal_link.STL" />
      </geometry>
      <material name="">
        <color rgba="1 1 1 1" />
      </material>
    </visual>
    <collision>
      <origin xyz="0 0 0" rpy="0 0 0" />
      <geometry>
        <mesh filename="package://x100_description/mesh/meshes_rohand_lites/L_lf_distal_link.STL" />
      </geometry>
    </collision>
  </link>

  <joint name="L_pinky_intermediate_joint" type="revolute">
    <origin xyz="-0.026922 -5.0837E-05 -0.010935" rpy="0 0 0" />
    <parent link="L_pinky_proximal" />
    <child link="L_pinky_intermediate" />
    <axis xyz="0 -1 0" />
    <limit lower="0" upper="1.7" effort="1" velocity="2.0" acceleration="5.0" />
    <mimic joint="L_pinky_proximal_joint" multiplier="1" offset="0" />
  </joint>


<!-- right hand -->


  <joint name="R_base_link_joint" type="fixed">
    <origin xyz="0 0 -0.049" rpy="0 -1.57 1.57"/>
    <parent link="right_wrist_yaw_link"/>
    <child link="R_hand_base_link"/>
  </joint>
  

  <link name="R_hand_base_link">
    <inertial>
      <origin xyz="-0.0576030661180955 0.00233560896319593 -0.00133218779459777" rpy="0 0 0" />
      <mass value="0.0493249140792959" />
      <inertia ixx="1.94571823302338E-05" ixy="-1.38729153384568E-06" ixz="1.07807983669446E-06"
               iyy="2.67719341990073E-05" iyz="-3.07356342974464E-07" izz="4.02773132726367E-05" />
    </inertial>
    <visual>
      <origin xyz="0 0 0" rpy="0 0 0" />
      <geometry>
        <mesh filename="package://x100_description/mesh/meshes_rohand_lites/R_base_link.STL" />
      </geometry>
      <material name="">
        <color rgba="1 1 1 1" />
      </material>
    </visual>
    <collision>
      <origin xyz="0 0 0" rpy="0 0 0" />
      <geometry>
        <mesh filename="package://x100_description/mesh/meshes_rohand_lites/R_base_link.STL" />
      </geometry>
    </collision>
  </link>

  <link name="R_thumb_proximal_base">
    <inertial>
      <origin xyz="-0.0191686509683619 -0.00572418793751744 -0.00158132841516827" rpy="0 0 0" />
      <mass value="0.00195350966248874" />
      <inertia ixx="1.65972225377993E-07" ixy="-7.97825490860689E-08" ixz="-1.04261831309922E-08"
               iyy="1.8111092952085E-07" iyz="-1.1733271461248E-08" izz="2.16718599283951E-07" />
    </inertial>
    <visual>
      <origin xyz="0 0 0" rpy="0 0 0" />
      <geometry>
        <mesh filename="package://x100_description/mesh/meshes_rohand_lites/R_th_root_link.STL" />
      </geometry>
      <material name="">
        <color rgba="1 1 1 1" />
      </material>
    </visual>
    <collision>
      <origin xyz="0 0 0" rpy="0 0 0" />
      <geometry>
        <mesh filename="package://x100_description/mesh/meshes_rohand_lites/R_th_root_link.STL" />
      </geometry>
    </collision>
  </link>

  <joint name="R_thumb_proximal_yaw_joint" type="revolute">
    <origin xyz="-0.025954 -0.01648 -0.019186" rpy="0.0078865 -0.22303 -0.035641" />
    <parent link="R_hand_base_link" />
    <child link="R_thumb_proximal_base" />
    <axis xyz="1 0 0" />
    <limit lower="-0.1" upper="1.7" effort="1" velocity="2.0" acceleration="5.0" />
  </joint>

  <link name="R_thumb_proximal">
    <inertial>
      <origin xyz="-0.0190126820702974 -0.00637807841543053 0.00769785866417869" rpy="0 0 0" />
      <mass value="0.00646388849033333" />
      <inertia ixx="5.07687345462868E-07" ixy="-4.14559349698037E-07" ixz="-1.8674365709823E-09"
               iyy="1.73768654791953E-06" iyz="-4.20029512218484E-10" izz="2.12756394178572E-06" />
    </inertial>
    <visual>
      <origin xyz="0 0 0" rpy="0 0 0" />
      <geometry>
        <mesh filename="package://x100_description/mesh/meshes_rohand_lites/R_th_proximal_link.STL" />
      </geometry>
      <material name="">
        <color rgba="1 1 1 1" />
      </material>
    </visual>
    <collision>
      <origin xyz="0 0 0" rpy="0 0 0" />
      <geometry>
        <mesh filename="package://x100_description/mesh/meshes_rohand_lites/R_th_proximal_link.STL" />
      </geometry>
    </collision>
  </link>

  <joint name="R_thumb_proximal_pitch_joint" type="revolute">
    <origin xyz="-0.028168 -0.020837 -0.010094" rpy="-0.0082402 0.00028649 0.034758" />
    <parent link="R_thumb_proximal_base" />
    <child link="R_thumb_proximal" />
    <axis xyz="0 0 -1" />
    <limit lower="0.0" upper="0.4" effort="1" velocity="2.0" acceleration="5.0" />
  </joint>

  <link name="R_thumb_distal">
    <inertial>
      <origin xyz="-0.0094593690473327 -0.0057218027674614 0.0068108911892128" rpy="0 0 0" />
      <mass value="0.00464616536496131" />
      <inertia ixx="1.70526363877279E-07" ixy="-1.70171405060127E-08" ixz="-3.06434125828904E-12"
               iyy="2.37897880292055E-07" iyz="1.31087369006255E-12" izz="2.09937364304614E-07" />
    </inertial>
    <visual>
      <origin xyz="0 0 0" rpy="0 0 0" />
      <geometry>
        <mesh filename="package://x100_description/mesh/meshes_rohand_lites/R_th_distal_link.STL" />
      </geometry>
      <material name="">
        <color rgba="1 1 1 1" />
      </material>
    </visual>
    <collision>
      <origin xyz="0 0 0" rpy="0 0 0" />
      <geometry>
        <mesh filename="package://x100_description/mesh/meshes_rohand_lites/R_th_distal_link.STL" />
      </geometry>
    </collision>
  </link>

  <joint name="R_thumb_distal_joint" type="revolute">
    <origin xyz="-0.048752 -0.010712 0.00087944" rpy="0 0 0" />
    <parent link="R_thumb_proximal" />
    <child link="R_thumb_distal" />
    <axis xyz="0 0 -1" />
    <limit lower="0" upper="1.2" effort="1" velocity="2.0" acceleration="5.0" />
    <mimic joint="R_thumb_proximal_pitch_joint" multiplier="1.0" offset="0" />
  </joint>

  <link name="R_index_proximal">
    <inertial>
      <origin xyz="-0.0143787205756178 0.0068202042615699 -0.00751216413311831" rpy="0 0 0" />
      <mass value="0.00205183706838826" />
      <inertia ixx="8.13016698160853E-08" ixy="1.51094306482205E-11" ixz="-2.88949821390807E-08"
               iyy="1.89783171251403E-07" iyz="4.65572959060812E-12" izz="1.96251769923446E-07" />
    </inertial>
    <visual>
      <origin xyz="0 0 0" rpy="0 0 0" />
      <geometry>
        <mesh filename="package://x100_description/mesh/meshes_rohand_lites/R_if_proximal_link.STL" />
      </geometry>
      <material name="">
        <color rgba="1 1 1 1" />
      </material>
    </visual>
    <collision>
      <origin xyz="0 0 0" rpy="0 0 0" />
      <geometry>
        <mesh filename="package://x100_description/mesh/meshes_rohand_lites/R_if_proximal_link.STL" />
      </geometry>
    </collision>
  </link>

  <joint name="R_index_proximal_joint" type="revolute">
    <origin xyz="-0.10859 -0.029338 -0.0013861" rpy="0.086779 -0.00311 0.035733" />
    <parent link="R_hand_base_link" />
    <child link="R_index_proximal" />
    <axis xyz="0 -1 0" />
    <limit lower="0" upper="1.2" effort="1" velocity="2.0" acceleration="5.0" />
  </joint>

  <link name="R_index_intermediate">
    <inertial>
      <origin xyz="-0.012222373112902 0.00644744577874212 -0.0159308052491082" rpy="0 0 0" />
      <mass value="0.00375868071914677" />
      <inertia ixx="2.6526744005835E-07" ixy="2.68139132185787E-10" ixz="-1.76013365071367E-07"
               iyy="4.17225025361236E-07" iyz="3.16739936806118E-10" izz="2.09518827365182E-07" />
    </inertial>
    <visual>
      <origin xyz="0 0 0" rpy="0 0 0" />
      <geometry>
        <mesh filename="package://x100_description/mesh/meshes_rohand_lites/R_if_distal_link.STL" />
      </geometry>
      <material name="">
        <color rgba="1 1 1 1" />
      </material>
    </visual>
    <collision>
      <origin xyz="0 0 0" rpy="0 0 0" />
      <geometry>
        <mesh filename="package://x100_description/mesh/meshes_rohand_lites/R_if_distal_link.STL" />
      </geometry>
    </collision>
  </link>

  <joint name="R_index_intermediate_joint" type="revolute">
    <origin xyz="-0.030875 0.00036803 -0.010625" rpy="0 0 0" />
    <parent link="R_index_proximal" />
    <child link="R_index_intermediate" />
    <axis xyz="0 -1 0" />
    <limit lower="0" upper="1.7" effort="1" velocity="2.0" acceleration="5.0" />
    <mimic joint="R_index_proximal_joint" multiplier="1" offset="0" />
  </joint>

  <link name="R_middle_proximal">
    <inertial>
      <origin xyz="-0.016329453759154 0.00649226533975397 -0.00963384586033489" rpy="0 0 0" />
      <mass value="0.00248843296883051" />
      <inertia ixx="1.10610510723197E-07" ixy="-5.89496390356217E-11" ixz="-6.05126652788143E-08"
               iyy="2.8446139484122E-07" iyz="-4.21063735821963E-11" izz="2.7312514865437E-07" />
    </inertial>
    <visual>
      <origin xyz="0 0 0" rpy="0 0 0" />
      <geometry>
        <mesh filename="package://x100_description/mesh/meshes_rohand_lites/R_mf_proximal_link.STL" />
      </geometry>
      <material name="">
        <color rgba="1 1 1 1" />
      </material>
    </visual>
    <collision>
      <origin xyz="0 0 0" rpy="0 0 0" />
      <geometry>
        <mesh filename="package://x100_description/mesh/meshes_rohand_lites/R_mf_proximal_link.STL" />
      </geometry>
    </collision>
  </link>

  <joint name="R_middle_proximal_joint" type="revolute">
    <origin xyz="-0.111168350336371 -0.0107315849401363 0.00310533319557881" rpy="-0.000165024105879644 0 -0.0341875332667528" />
    <parent link="R_hand_base_link" />
    <child link="R_middle_proximal" />
    <axis xyz="0 -1 0" />
    <limit lower="0" upper="1.2" effort="1" velocity="2.0" acceleration="5.0" />
  </joint>

  <link name="R_middle_intermediate">
    <inertial>
      <origin xyz="-0.0117807102189178 0.00644198393359627 -0.0162599790204698" rpy="0 0 0" />
      <mass value="0.00375867884267013" />
      <inertia ixx="2.74876926237726E-07" ixy="2.59466981378291E-10" ixz="-1.7421907947615E-07"
               iyy="4.1722285891413E-07" iyz="3.23406111565757E-10" izz="1.99906902685593E-07" />
    </inertial>
    <visual>
      <origin xyz="0 0 0" rpy="0 0 0" />
      <geometry>
        <mesh filename="package://x100_description/mesh/meshes_rohand_lites/R_mf_distal_link.STL" />
      </geometry>
      <material name="">
        <color rgba="1 1 1 1" />
      </material>
    </visual>
    <collision>
      <origin xyz="0 0 0" rpy="0 0 0" />
      <geometry>
        <mesh filename="package://x100_description/mesh/meshes_rohand_lites/R_mf_distal_link.STL" />
      </geometry>
    </collision>
  </link>

  <joint name="R_middle_intermediate_joint" type="revolute">
    <origin xyz="-0.0348440227740655 5.03497035553302E-05 -0.0137271073982339" rpy="-0.00439882751506536 -0.000117257737364924 0.00753742768873965" />
    <parent link="R_middle_proximal" />
    <child link="R_middle_intermediate" />
    <axis xyz="0 -1 0" />
    <limit lower="0" upper="1.7" effort="1" velocity="2.0" acceleration="5.0" />
    <mimic joint="R_middle_proximal_joint" multiplier="1" offset="0" />
  </joint>

  <link name="R_ring_proximal">
    <inertial>
      <origin xyz="-0.0143549280434906 0.00682023657911832 -0.00755778479766486" rpy="0 0 0" />
      <mass value="0.00205187294843744" />
      <inertia ixx="8.14868585707663E-08" ixy="1.41861573407726E-11" ixz="-2.9259876910324E-08"
               iyy="1.89786107772236E-07" iyz="4.79988274178486E-12" izz="1.960702878707E-07" />
    </inertial>
    <visual>
      <origin xyz="0 0 0" rpy="0 0 0" />
      <geometry>
        <mesh filename="package://x100_description/mesh/meshes_rohand_lites/R_rf_proximal_link.STL" />
      </geometry>
      <material name="">
        <color rgba="1 1 1 1" />
      </material>
    </visual>
    <collision>
      <origin xyz="0 0 0" rpy="0 0 0" />
      <geometry>
        <mesh filename="package://x100_description/mesh/meshes_rohand_lites/R_rf_proximal_link.STL" />
      </geometry>
    </collision>
  </link>

  <joint name="R_ring_proximal_joint" type="revolute">
    <origin xyz="-0.10829 0.007056 0.0024304" rpy="0.00015789 1.6485E-05 -0.10403" />
    <parent link="R_hand_base_link" />
    <child link="R_ring_proximal" />
    <axis xyz="0 -1 0" />
    <limit lower="0" upper="1.2" effort="1" velocity="2.0" acceleration="5.0" />
  </joint>

  <link name="R_ring_intermediate">
    <inertial>
      <origin xyz="-0.0121787543720058 0.0064475580290749 -0.0159643969071744" rpy="0 0 0" />
      <mass value="0.00375873422510174" />
      <inertia ixx="2.66234188468105E-07" ixy="2.66619623996111E-10" ixz="-1.75861376428997E-07"
               iyy="4.17230114265725E-07" iyz="3.17193421265111E-10" izz="2.0855875648093E-07" />
    </inertial>
    <visual>
      <origin xyz="0 0 0" rpy="0 0 0" />
      <geometry>
        <mesh filename="package://x100_description/mesh/meshes_rohand_lites/R_rf_distal_link.STL" />
      </geometry>
      <material name="">
        <color rgba="1 1 1 1" />
      </material>
    </visual>
    <collision>
      <origin xyz="0 0 0" rpy="0 0 0" />
      <geometry>
        <mesh filename="package://x100_description/mesh/meshes_rohand_lites/R_rf_distal_link.STL" />
      </geometry>
    </collision>
  </link>

  <joint name="R_ring_intermediate_joint" type="revolute">
    <origin xyz="-0.030791 0.00036828 -0.010696" rpy="-0.0042136 -0.0004074 0.0076437" />
    <parent link="R_ring_proximal" />
    <child link="R_ring_intermediate" />
    <axis xyz="0 -1 0" />
    <limit lower="0" upper="1.7" effort="1" velocity="2.0" acceleration="5.0" />
    <mimic joint="R_ring_proximal_joint" multiplier="1" offset="0" />
  </joint>

  <link name="R_pinky_proximal">
    <inertial>
      <origin xyz="-0.0127241110356107 0.00649957990170523 -0.00744483846071534" rpy="0 0 0" />
      <mass value="0.00183686407359195" />
      <inertia ixx="7.25936420936618E-08" ixy="1.26029064472353E-12" ixz="-2.19325321953627E-08"
               iyy="1.40948330406022E-07" iyz="-3.97609924901949E-13" izz="1.47282231216297E-07" />
    </inertial>
    <visual>
      <origin xyz="0 0 0" rpy="0 0 0" />
      <geometry>
        <mesh filename="package://x100_description/mesh/meshes_rohand_lites/R_lf_proximal_link.STL" />
      </geometry>
      <material name="">
        <color rgba="1 1 1 1" />
      </material>
    </visual>
    <collision>
      <origin xyz="0 0 0" rpy="0 0 0" />
      <geometry>
        <mesh filename="package://x100_description/mesh/meshes_rohand_lites/R_lf_proximal_link.STL" />
      </geometry>
    </collision>
  </link>

  <joint name="R_pinky_proximal_joint" type="revolute">
    <origin xyz="-0.10436 0.025536 0.00068678" rpy="-0.086826 -0.014497 -0.16502" />
    <parent link="R_hand_base_link" />
    <child link="R_pinky_proximal" />
    <axis xyz="0 -1 0" />
    <limit lower="0" upper="1.2" effort="1" velocity="2.0" acceleration="5.0" />
  </joint>

  <link name="R_pinky_intermediate">
    <inertial>
      <origin xyz="-0.00660185291159945 0.00644841570480648 -0.0134694736191499" rpy="0 0 0" />
      <mass value="0.00243556509111398" />
      <inertia ixx="1.18626211477515E-07" ixy="9.45828083556239E-11" ixz="-4.33572574582032E-08"
               iyy="1.41808396396924E-07" iyz="1.67029567238108E-10" izz="5.46901618733586E-08" />
    </inertial>
    <visual>
      <origin xyz="0 0 0" rpy="0 0 0" />
      <geometry>
        <mesh filename="package://x100_description/mesh/meshes_rohand_lites/R_lf_distal_link.STL" />
      </geometry>
      <material name="">
        <color rgba="1 1 1 1" />
      </material>
    </visual>
    <collision>
      <origin xyz="0 0 0" rpy="0 0 0" />
      <geometry>
        <mesh filename="package://x100_description/mesh/meshes_rohand_lites/R_lf_distal_link.STL" />
      </geometry>
    </collision>
  </link>

  <joint name="R_pinky_intermediate_joint" type="revolute">
    <origin xyz="-0.026989 5.0837E-05 -0.010769" rpy="0 0 0" />
    <parent link="R_pinky_proximal" />
    <child link="R_pinky_intermediate" />
    <axis xyz="0 -1 0" />
    <limit lower="0" upper="1.7" effort="1" velocity="2.0" acceleration="5.0" />
    <mimic joint="R_pinky_proximal_joint" multiplier="1" offset="0" />
  </joint>


</robot>